INFO:     Will watch for changes in these directories: ['/root/IT3530-Project/server']
INFO:     Uvicorn running on http://0.0.0.0:80 (Press CTRL+C to quit)
INFO:     Started reloader process [2132] using watchgod
Process SpawnProcess-1:
Traceback (most recent call last):
  File "/usr/lib/python3.7/multiprocessing/process.py", line 297, in _bootstrap
    self.run()
  File "/usr/lib/python3.7/multiprocessing/process.py", line 99, in run
    self._target(*self._args, **self._kwargs)
  File "/usr/local/lib/python3.7/dist-packages/uvicorn/subprocess.py", line 76, in subprocess_started
    target(sockets=sockets)
  File "/usr/local/lib/python3.7/dist-packages/uvicorn/server.py", line 68, in run
    return asyncio.run(self.serve(sockets=sockets))
  File "/usr/lib/python3.7/asyncio/runners.py", line 43, in run
    return loop.run_until_complete(main)
  File "uvloop/loop.pyx", line 1501, in uvloop.loop.Loop.run_until_complete
  File "/usr/local/lib/python3.7/dist-packages/uvicorn/server.py", line 76, in serve
    config.load()
  File "/usr/local/lib/python3.7/dist-packages/uvicorn/config.py", line 448, in load
    self.loaded_app = import_from_string(self.app)
  File "/usr/local/lib/python3.7/dist-packages/uvicorn/importer.py", line 24, in import_from_string
    raise exc from None
  File "/usr/local/lib/python3.7/dist-packages/uvicorn/importer.py", line 21, in import_from_string
    module = importlib.import_module(module_str)
  File "/usr/lib/python3.7/importlib/__init__.py", line 127, in import_module
    return _bootstrap._gcd_import(name[level:], package, level)
  File "<frozen importlib._bootstrap>", line 1006, in _gcd_import
  File "<frozen importlib._bootstrap>", line 983, in _find_and_load
  File "<frozen importlib._bootstrap>", line 967, in _find_and_load_unlocked
  File "<frozen importlib._bootstrap>", line 677, in _load_unlocked
  File "<frozen importlib._bootstrap_external>", line 728, in exec_module
  File "<frozen importlib._bootstrap>", line 219, in _call_with_frames_removed
  File "./main.py", line 2, in <module>
    from fastapi import FastAPI, Form, Response, Cookie, FileResponse
ImportError: cannot import name 'FileResponse' from 'fastapi' (/usr/local/lib/python3.7/dist-packages/fastapi/__init__.py)
WARNING:  WatchGodReload detected file change in '['/root/IT3530-Project/server/main.py']'. Reloading...
./main.py:9: RuntimeWarning: This channel is already in use, continuing anyway.  Use GPIO.setwarnings(False) to disable warnings.
  GPIO.setup(20, GPIO.OUT)
INFO:     Started server process [2176]
INFO:uvicorn.error:Started server process [2176]
INFO:     Waiting for application startup.
INFO:uvicorn.error:Waiting for application startup.
INFO:     Application startup complete.
INFO:uvicorn.error:Application startup complete.
INFO:     10.20.41.203:0 - "GET / HTTP/1.1" 500 Internal Server Error
ERROR:    Exception in ASGI application
Traceback (most recent call last):
  File "/usr/local/lib/python3.7/dist-packages/uvicorn/protocols/http/httptools_impl.py", line 375, in run_asgi
    result = await app(self.scope, self.receive, self.send)
  File "/usr/local/lib/python3.7/dist-packages/uvicorn/middleware/proxy_headers.py", line 75, in __call__
    return await self.app(scope, receive, send)
  File "/usr/local/lib/python3.7/dist-packages/fastapi/applications.py", line 208, in __call__
    await super().__call__(scope, receive, send)
  File "/usr/local/lib/python3.7/dist-packages/starlette/applications.py", line 112, in __call__
    await self.middleware_stack(scope, receive, send)
  File "/usr/local/lib/python3.7/dist-packages/starlette/middleware/errors.py", line 181, in __call__
    raise exc
  File "/usr/local/lib/python3.7/dist-packages/starlette/middleware/errors.py", line 159, in __call__
    await self.app(scope, receive, _send)
  File "/usr/local/lib/python3.7/dist-packages/starlette/exceptions.py", line 82, in __call__
    raise exc
  File "/usr/local/lib/python3.7/dist-packages/starlette/exceptions.py", line 71, in __call__
    await self.app(scope, receive, sender)
  File "/usr/local/lib/python3.7/dist-packages/starlette/routing.py", line 656, in __call__
    await route.handle(scope, receive, send)
  File "/usr/local/lib/python3.7/dist-packages/starlette/routing.py", line 259, in handle
    await self.app(scope, receive, send)
  File "/usr/local/lib/python3.7/dist-packages/starlette/routing.py", line 61, in app
    response = await func(request)
  File "/usr/local/lib/python3.7/dist-packages/fastapi/routing.py", line 227, in app
    dependant=dependant, values=values, is_coroutine=is_coroutine
  File "/usr/local/lib/python3.7/dist-packages/fastapi/routing.py", line 161, in run_endpoint_function
    return await run_in_threadpool(dependant.call, **values)
  File "/usr/local/lib/python3.7/dist-packages/starlette/concurrency.py", line 39, in run_in_threadpool
    return await anyio.to_thread.run_sync(func, *args)
  File "/usr/local/lib/python3.7/dist-packages/anyio/to_thread.py", line 29, in run_sync
    limiter=limiter)
  File "/usr/local/lib/python3.7/dist-packages/anyio/_backends/_asyncio.py", line 818, in run_sync_in_worker_thread
    return await future
  File "/usr/local/lib/python3.7/dist-packages/anyio/_backends/_asyncio.py", line 754, in run
    result = context.run(func, *args)
  File "./main.py", line 42, in index
    f = open("./client/index.html","r")
FileNotFoundError: [Errno 2] No such file or directory: './client/index.html'
ERROR:uvicorn.error:Exception in ASGI application
Traceback (most recent call last):
  File "/usr/local/lib/python3.7/dist-packages/uvicorn/protocols/http/httptools_impl.py", line 375, in run_asgi
    result = await app(self.scope, self.receive, self.send)
  File "/usr/local/lib/python3.7/dist-packages/uvicorn/middleware/proxy_headers.py", line 75, in __call__
    return await self.app(scope, receive, send)
  File "/usr/local/lib/python3.7/dist-packages/fastapi/applications.py", line 208, in __call__
    await super().__call__(scope, receive, send)
  File "/usr/local/lib/python3.7/dist-packages/starlette/applications.py", line 112, in __call__
    await self.middleware_stack(scope, receive, send)
  File "/usr/local/lib/python3.7/dist-packages/starlette/middleware/errors.py", line 181, in __call__
    raise exc
  File "/usr/local/lib/python3.7/dist-packages/starlette/middleware/errors.py", line 159, in __call__
    await self.app(scope, receive, _send)
  File "/usr/local/lib/python3.7/dist-packages/starlette/exceptions.py", line 82, in __call__
    raise exc
  File "/usr/local/lib/python3.7/dist-packages/starlette/exceptions.py", line 71, in __call__
    await self.app(scope, receive, sender)
  File "/usr/local/lib/python3.7/dist-packages/starlette/routing.py", line 656, in __call__
    await route.handle(scope, receive, send)
  File "/usr/local/lib/python3.7/dist-packages/starlette/routing.py", line 259, in handle
    await self.app(scope, receive, send)
  File "/usr/local/lib/python3.7/dist-packages/starlette/routing.py", line 61, in app
    response = await func(request)
  File "/usr/local/lib/python3.7/dist-packages/fastapi/routing.py", line 227, in app
    dependant=dependant, values=values, is_coroutine=is_coroutine
  File "/usr/local/lib/python3.7/dist-packages/fastapi/routing.py", line 161, in run_endpoint_function
    return await run_in_threadpool(dependant.call, **values)
  File "/usr/local/lib/python3.7/dist-packages/starlette/concurrency.py", line 39, in run_in_threadpool
    return await anyio.to_thread.run_sync(func, *args)
  File "/usr/local/lib/python3.7/dist-packages/anyio/to_thread.py", line 29, in run_sync
    limiter=limiter)
  File "/usr/local/lib/python3.7/dist-packages/anyio/_backends/_asyncio.py", line 818, in run_sync_in_worker_thread
    return await future
  File "/usr/local/lib/python3.7/dist-packages/anyio/_backends/_asyncio.py", line 754, in run
    result = context.run(func, *args)
  File "./main.py", line 42, in index
    f = open("./client/index.html","r")
FileNotFoundError: [Errno 2] No such file or directory: './client/index.html'
INFO:     10.20.41.203:0 - "GET / HTTP/1.1" 500 Internal Server Error
ERROR:    Exception in ASGI application
Traceback (most recent call last):
  File "/usr/local/lib/python3.7/dist-packages/uvicorn/protocols/http/httptools_impl.py", line 375, in run_asgi
    result = await app(self.scope, self.receive, self.send)
  File "/usr/local/lib/python3.7/dist-packages/uvicorn/middleware/proxy_headers.py", line 75, in __call__
    return await self.app(scope, receive, send)
  File "/usr/local/lib/python3.7/dist-packages/fastapi/applications.py", line 208, in __call__
    await super().__call__(scope, receive, send)
  File "/usr/local/lib/python3.7/dist-packages/starlette/applications.py", line 112, in __call__
    await self.middleware_stack(scope, receive, send)
  File "/usr/local/lib/python3.7/dist-packages/starlette/middleware/errors.py", line 181, in __call__
    raise exc
  File "/usr/local/lib/python3.7/dist-packages/starlette/middleware/errors.py", line 159, in __call__
    await self.app(scope, receive, _send)
  File "/usr/local/lib/python3.7/dist-packages/starlette/exceptions.py", line 82, in __call__
    raise exc
  File "/usr/local/lib/python3.7/dist-packages/starlette/exceptions.py", line 71, in __call__
    await self.app(scope, receive, sender)
  File "/usr/local/lib/python3.7/dist-packages/starlette/routing.py", line 656, in __call__
    await route.handle(scope, receive, send)
  File "/usr/local/lib/python3.7/dist-packages/starlette/routing.py", line 259, in handle
    await self.app(scope, receive, send)
  File "/usr/local/lib/python3.7/dist-packages/starlette/routing.py", line 61, in app
    response = await func(request)
  File "/usr/local/lib/python3.7/dist-packages/fastapi/routing.py", line 227, in app
    dependant=dependant, values=values, is_coroutine=is_coroutine
  File "/usr/local/lib/python3.7/dist-packages/fastapi/routing.py", line 161, in run_endpoint_function
    return await run_in_threadpool(dependant.call, **values)
  File "/usr/local/lib/python3.7/dist-packages/starlette/concurrency.py", line 39, in run_in_threadpool
    return await anyio.to_thread.run_sync(func, *args)
  File "/usr/local/lib/python3.7/dist-packages/anyio/to_thread.py", line 29, in run_sync
    limiter=limiter)
  File "/usr/local/lib/python3.7/dist-packages/anyio/_backends/_asyncio.py", line 818, in run_sync_in_worker_thread
    return await future
  File "/usr/local/lib/python3.7/dist-packages/anyio/_backends/_asyncio.py", line 754, in run
    result = context.run(func, *args)
  File "./main.py", line 42, in index
    f = open("./client/index.html","r")
FileNotFoundError: [Errno 2] No such file or directory: './client/index.html'
ERROR:uvicorn.error:Exception in ASGI application
Traceback (most recent call last):
  File "/usr/local/lib/python3.7/dist-packages/uvicorn/protocols/http/httptools_impl.py", line 375, in run_asgi
    result = await app(self.scope, self.receive, self.send)
  File "/usr/local/lib/python3.7/dist-packages/uvicorn/middleware/proxy_headers.py", line 75, in __call__
    return await self.app(scope, receive, send)
  File "/usr/local/lib/python3.7/dist-packages/fastapi/applications.py", line 208, in __call__
    await super().__call__(scope, receive, send)
  File "/usr/local/lib/python3.7/dist-packages/starlette/applications.py", line 112, in __call__
    await self.middleware_stack(scope, receive, send)
  File "/usr/local/lib/python3.7/dist-packages/starlette/middleware/errors.py", line 181, in __call__
    raise exc
  File "/usr/local/lib/python3.7/dist-packages/starlette/middleware/errors.py", line 159, in __call__
    await self.app(scope, receive, _send)
  File "/usr/local/lib/python3.7/dist-packages/starlette/exceptions.py", line 82, in __call__
    raise exc
  File "/usr/local/lib/python3.7/dist-packages/starlette/exceptions.py", line 71, in __call__
    await self.app(scope, receive, sender)
  File "/usr/local/lib/python3.7/dist-packages/starlette/routing.py", line 656, in __call__
    await route.handle(scope, receive, send)
  File "/usr/local/lib/python3.7/dist-packages/starlette/routing.py", line 259, in handle
    await self.app(scope, receive, send)
  File "/usr/local/lib/python3.7/dist-packages/starlette/routing.py", line 61, in app
    response = await func(request)
  File "/usr/local/lib/python3.7/dist-packages/fastapi/routing.py", line 227, in app
    dependant=dependant, values=values, is_coroutine=is_coroutine
  File "/usr/local/lib/python3.7/dist-packages/fastapi/routing.py", line 161, in run_endpoint_function
    return await run_in_threadpool(dependant.call, **values)
  File "/usr/local/lib/python3.7/dist-packages/starlette/concurrency.py", line 39, in run_in_threadpool
    return await anyio.to_thread.run_sync(func, *args)
  File "/usr/local/lib/python3.7/dist-packages/anyio/to_thread.py", line 29, in run_sync
    limiter=limiter)
  File "/usr/local/lib/python3.7/dist-packages/anyio/_backends/_asyncio.py", line 818, in run_sync_in_worker_thread
    return await future
  File "/usr/local/lib/python3.7/dist-packages/anyio/_backends/_asyncio.py", line 754, in run
    result = context.run(func, *args)
  File "./main.py", line 42, in index
    f = open("./client/index.html","r")
FileNotFoundError: [Errno 2] No such file or directory: './client/index.html'
INFO:     10.20.41.203:0 - "GET / HTTP/1.1" 500 Internal Server Error
ERROR:    Exception in ASGI application
Traceback (most recent call last):
  File "/usr/local/lib/python3.7/dist-packages/uvicorn/protocols/http/httptools_impl.py", line 375, in run_asgi
    result = await app(self.scope, self.receive, self.send)
  File "/usr/local/lib/python3.7/dist-packages/uvicorn/middleware/proxy_headers.py", line 75, in __call__
    return await self.app(scope, receive, send)
  File "/usr/local/lib/python3.7/dist-packages/fastapi/applications.py", line 208, in __call__
    await super().__call__(scope, receive, send)
  File "/usr/local/lib/python3.7/dist-packages/starlette/applications.py", line 112, in __call__
    await self.middleware_stack(scope, receive, send)
  File "/usr/local/lib/python3.7/dist-packages/starlette/middleware/errors.py", line 181, in __call__
    raise exc
  File "/usr/local/lib/python3.7/dist-packages/starlette/middleware/errors.py", line 159, in __call__
    await self.app(scope, receive, _send)
  File "/usr/local/lib/python3.7/dist-packages/starlette/exceptions.py", line 82, in __call__
    raise exc
  File "/usr/local/lib/python3.7/dist-packages/starlette/exceptions.py", line 71, in __call__
    await self.app(scope, receive, sender)
  File "/usr/local/lib/python3.7/dist-packages/starlette/routing.py", line 656, in __call__
    await route.handle(scope, receive, send)
  File "/usr/local/lib/python3.7/dist-packages/starlette/routing.py", line 259, in handle
    await self.app(scope, receive, send)
  File "/usr/local/lib/python3.7/dist-packages/starlette/routing.py", line 61, in app
    response = await func(request)
  File "/usr/local/lib/python3.7/dist-packages/fastapi/routing.py", line 227, in app
    dependant=dependant, values=values, is_coroutine=is_coroutine
  File "/usr/local/lib/python3.7/dist-packages/fastapi/routing.py", line 161, in run_endpoint_function
    return await run_in_threadpool(dependant.call, **values)
  File "/usr/local/lib/python3.7/dist-packages/starlette/concurrency.py", line 39, in run_in_threadpool
    return await anyio.to_thread.run_sync(func, *args)
  File "/usr/local/lib/python3.7/dist-packages/anyio/to_thread.py", line 29, in run_sync
    limiter=limiter)
  File "/usr/local/lib/python3.7/dist-packages/anyio/_backends/_asyncio.py", line 818, in run_sync_in_worker_thread
    return await future
  File "/usr/local/lib/python3.7/dist-packages/anyio/_backends/_asyncio.py", line 754, in run
    result = context.run(func, *args)
  File "./main.py", line 42, in index
    f = open("./client/index.html","r")
FileNotFoundError: [Errno 2] No such file or directory: './client/index.html'
ERROR:uvicorn.error:Exception in ASGI application
Traceback (most recent call last):
  File "/usr/local/lib/python3.7/dist-packages/uvicorn/protocols/http/httptools_impl.py", line 375, in run_asgi
    result = await app(self.scope, self.receive, self.send)
  File "/usr/local/lib/python3.7/dist-packages/uvicorn/middleware/proxy_headers.py", line 75, in __call__
    return await self.app(scope, receive, send)
  File "/usr/local/lib/python3.7/dist-packages/fastapi/applications.py", line 208, in __call__
    await super().__call__(scope, receive, send)
  File "/usr/local/lib/python3.7/dist-packages/starlette/applications.py", line 112, in __call__
    await self.middleware_stack(scope, receive, send)
  File "/usr/local/lib/python3.7/dist-packages/starlette/middleware/errors.py", line 181, in __call__
    raise exc
  File "/usr/local/lib/python3.7/dist-packages/starlette/middleware/errors.py", line 159, in __call__
    await self.app(scope, receive, _send)
  File "/usr/local/lib/python3.7/dist-packages/starlette/exceptions.py", line 82, in __call__
    raise exc
  File "/usr/local/lib/python3.7/dist-packages/starlette/exceptions.py", line 71, in __call__
    await self.app(scope, receive, sender)
  File "/usr/local/lib/python3.7/dist-packages/starlette/routing.py", line 656, in __call__
    await route.handle(scope, receive, send)
  File "/usr/local/lib/python3.7/dist-packages/starlette/routing.py", line 259, in handle
    await self.app(scope, receive, send)
  File "/usr/local/lib/python3.7/dist-packages/starlette/routing.py", line 61, in app
    response = await func(request)
  File "/usr/local/lib/python3.7/dist-packages/fastapi/routing.py", line 227, in app
    dependant=dependant, values=values, is_coroutine=is_coroutine
  File "/usr/local/lib/python3.7/dist-packages/fastapi/routing.py", line 161, in run_endpoint_function
    return await run_in_threadpool(dependant.call, **values)
  File "/usr/local/lib/python3.7/dist-packages/starlette/concurrency.py", line 39, in run_in_threadpool
    return await anyio.to_thread.run_sync(func, *args)
  File "/usr/local/lib/python3.7/dist-packages/anyio/to_thread.py", line 29, in run_sync
    limiter=limiter)
  File "/usr/local/lib/python3.7/dist-packages/anyio/_backends/_asyncio.py", line 818, in run_sync_in_worker_thread
    return await future
  File "/usr/local/lib/python3.7/dist-packages/anyio/_backends/_asyncio.py", line 754, in run
    result = context.run(func, *args)
  File "./main.py", line 42, in index
    f = open("./client/index.html","r")
FileNotFoundError: [Errno 2] No such file or directory: './client/index.html'
INFO:     10.20.41.203:0 - "GET /getImage HTTP/1.1" 422 Unprocessable Entity
INFO:     10.20.41.203:0 - "GET /getImage?monthAndDayAndHourAndMinAndImageID=a.jpg HTTP/1.1" 200 OK
INFO:     10.20.41.203:0 - "GET /login HTTP/1.1" 200 OK
DEBUG:multipart.multipart:Calling on_field_start with no data
DEBUG:multipart.multipart:Calling on_field_name with data[0:3]
DEBUG:multipart.multipart:Calling on_field_data with data[4:22]
DEBUG:multipart.multipart:Calling on_field_end with no data
DEBUG:multipart.multipart:Calling on_end with no data
INFO:     10.20.41.203:0 - "POST /getToken HTTP/1.1" 200 OK
INFO:     10.20.41.203:0 - "GET / HTTP/1.1" 500 Internal Server Error
ERROR:    Exception in ASGI application
Traceback (most recent call last):
  File "/usr/local/lib/python3.7/dist-packages/uvicorn/protocols/http/httptools_impl.py", line 375, in run_asgi
    result = await app(self.scope, self.receive, self.send)
  File "/usr/local/lib/python3.7/dist-packages/uvicorn/middleware/proxy_headers.py", line 75, in __call__
    return await self.app(scope, receive, send)
  File "/usr/local/lib/python3.7/dist-packages/fastapi/applications.py", line 208, in __call__
    await super().__call__(scope, receive, send)
  File "/usr/local/lib/python3.7/dist-packages/starlette/applications.py", line 112, in __call__
    await self.middleware_stack(scope, receive, send)
  File "/usr/local/lib/python3.7/dist-packages/starlette/middleware/errors.py", line 181, in __call__
    raise exc
  File "/usr/local/lib/python3.7/dist-packages/starlette/middleware/errors.py", line 159, in __call__
    await self.app(scope, receive, _send)
  File "/usr/local/lib/python3.7/dist-packages/starlette/exceptions.py", line 82, in __call__
    raise exc
  File "/usr/local/lib/python3.7/dist-packages/starlette/exceptions.py", line 71, in __call__
    await self.app(scope, receive, sender)
  File "/usr/local/lib/python3.7/dist-packages/starlette/routing.py", line 656, in __call__
    await route.handle(scope, receive, send)
  File "/usr/local/lib/python3.7/dist-packages/starlette/routing.py", line 259, in handle
    await self.app(scope, receive, send)
  File "/usr/local/lib/python3.7/dist-packages/starlette/routing.py", line 61, in app
    response = await func(request)
  File "/usr/local/lib/python3.7/dist-packages/fastapi/routing.py", line 227, in app
    dependant=dependant, values=values, is_coroutine=is_coroutine
  File "/usr/local/lib/python3.7/dist-packages/fastapi/routing.py", line 161, in run_endpoint_function
    return await run_in_threadpool(dependant.call, **values)
  File "/usr/local/lib/python3.7/dist-packages/starlette/concurrency.py", line 39, in run_in_threadpool
    return await anyio.to_thread.run_sync(func, *args)
  File "/usr/local/lib/python3.7/dist-packages/anyio/to_thread.py", line 29, in run_sync
    limiter=limiter)
  File "/usr/local/lib/python3.7/dist-packages/anyio/_backends/_asyncio.py", line 818, in run_sync_in_worker_thread
    return await future
  File "/usr/local/lib/python3.7/dist-packages/anyio/_backends/_asyncio.py", line 754, in run
    result = context.run(func, *args)
  File "./main.py", line 42, in index
    f = open("./client/index.html","r")
FileNotFoundError: [Errno 2] No such file or directory: './client/index.html'
ERROR:uvicorn.error:Exception in ASGI application
Traceback (most recent call last):
  File "/usr/local/lib/python3.7/dist-packages/uvicorn/protocols/http/httptools_impl.py", line 375, in run_asgi
    result = await app(self.scope, self.receive, self.send)
  File "/usr/local/lib/python3.7/dist-packages/uvicorn/middleware/proxy_headers.py", line 75, in __call__
    return await self.app(scope, receive, send)
  File "/usr/local/lib/python3.7/dist-packages/fastapi/applications.py", line 208, in __call__
    await super().__call__(scope, receive, send)
  File "/usr/local/lib/python3.7/dist-packages/starlette/applications.py", line 112, in __call__
    await self.middleware_stack(scope, receive, send)
  File "/usr/local/lib/python3.7/dist-packages/starlette/middleware/errors.py", line 181, in __call__
    raise exc
  File "/usr/local/lib/python3.7/dist-packages/starlette/middleware/errors.py", line 159, in __call__
    await self.app(scope, receive, _send)
  File "/usr/local/lib/python3.7/dist-packages/starlette/exceptions.py", line 82, in __call__
    raise exc
  File "/usr/local/lib/python3.7/dist-packages/starlette/exceptions.py", line 71, in __call__
    await self.app(scope, receive, sender)
  File "/usr/local/lib/python3.7/dist-packages/starlette/routing.py", line 656, in __call__
    await route.handle(scope, receive, send)
  File "/usr/local/lib/python3.7/dist-packages/starlette/routing.py", line 259, in handle
    await self.app(scope, receive, send)
  File "/usr/local/lib/python3.7/dist-packages/starlette/routing.py", line 61, in app
    response = await func(request)
  File "/usr/local/lib/python3.7/dist-packages/fastapi/routing.py", line 227, in app
    dependant=dependant, values=values, is_coroutine=is_coroutine
  File "/usr/local/lib/python3.7/dist-packages/fastapi/routing.py", line 161, in run_endpoint_function
    return await run_in_threadpool(dependant.call, **values)
  File "/usr/local/lib/python3.7/dist-packages/starlette/concurrency.py", line 39, in run_in_threadpool
    return await anyio.to_thread.run_sync(func, *args)
  File "/usr/local/lib/python3.7/dist-packages/anyio/to_thread.py", line 29, in run_sync
    limiter=limiter)
  File "/usr/local/lib/python3.7/dist-packages/anyio/_backends/_asyncio.py", line 818, in run_sync_in_worker_thread
    return await future
  File "/usr/local/lib/python3.7/dist-packages/anyio/_backends/_asyncio.py", line 754, in run
    result = context.run(func, *args)
  File "./main.py", line 42, in index
    f = open("./client/index.html","r")
FileNotFoundError: [Errno 2] No such file or directory: './client/index.html'
INFO:     10.20.41.203:0 - "GET /getImage?monthAndDayAndHourAndMinAndImageID=a.jpg HTTP/1.1" 200 OK
INFO:     10.20.41.203:0 - "GET /getImage?monthAndDayAndHourAndMinAndImageID=a.jpg HTTP/1.1" 200 OK
INFO:     10.20.41.203:0 - "GET /getMonths_images HTTP/1.1" 200 OK
WARNING:  WatchGodReload detected file change in '['/root/IT3530-Project/server/main.py']'. Reloading...
INFO:     Shutting down
INFO:uvicorn.error:Shutting down
INFO:     Waiting for application shutdown.
INFO:uvicorn.error:Waiting for application shutdown.
INFO:     Application shutdown complete.
INFO:uvicorn.error:Application shutdown complete.
INFO:     Finished server process [2176]
INFO:uvicorn.error:Finished server process [2176]
ERROR:    Error loading ASGI app. Could not import module "main".
WARNING:  WatchGodReload detected file change in '['/root/IT3530-Project/server/main.py']'. Reloading...
./main.py:9: RuntimeWarning: This channel is already in use, continuing anyway.  Use GPIO.setwarnings(False) to disable warnings.
  GPIO.setup(20, GPIO.OUT)
INFO:     Started server process [2242]
INFO:uvicorn.error:Started server process [2242]
INFO:     Waiting for application startup.
INFO:uvicorn.error:Waiting for application startup.
INFO:     Application startup complete.
INFO:uvicorn.error:Application startup complete.
INFO:     10.20.40.10:0 - "GET /getMonths_images HTTP/1.1" 200 OK
WARNING:  WatchGodReload detected file change in '['/root/IT3530-Project/server/main.py']'. Reloading...
INFO:     Shutting down
INFO:uvicorn.error:Shutting down
INFO:     Waiting for application shutdown.
INFO:uvicorn.error:Waiting for application shutdown.
INFO:     Application shutdown complete.
INFO:uvicorn.error:Application shutdown complete.
INFO:     Finished server process [2242]
INFO:uvicorn.error:Finished server process [2242]
./main.py:9: RuntimeWarning: This channel is already in use, continuing anyway.  Use GPIO.setwarnings(False) to disable warnings.
  GPIO.setup(20, GPIO.OUT)
INFO:     Started server process [2257]
INFO:uvicorn.error:Started server process [2257]
INFO:     Waiting for application startup.
INFO:uvicorn.error:Waiting for application startup.
INFO:     Application startup complete.
INFO:uvicorn.error:Application startup complete.
(3074988063023060608687147585512158741587561644588424652211562392651586193521671446342635542539105450806059648219100497482786801278268106785807719225707393, 10215636925397142776245256898380230542584179652686351003791624400273636359771288415804136972192345722374345459074869078741666462602305310615680948140613319)
INFO:     10.20.40.10:0 - "GET /getMonths_images HTTP/1.1" 200 OK
WARNING:  WatchGodReload detected file change in '['/root/IT3530-Project/server/main.py']'. Reloading...
INFO:     Shutting down
INFO:uvicorn.error:Shutting down
INFO:     Waiting for application shutdown.
INFO:uvicorn.error:Waiting for application shutdown.
INFO:     Application shutdown complete.
INFO:uvicorn.error:Application shutdown complete.
INFO:     Finished server process [2257]
INFO:uvicorn.error:Finished server process [2257]
./main.py:9: RuntimeWarning: This channel is already in use, continuing anyway.  Use GPIO.setwarnings(False) to disable warnings.
  GPIO.setup(20, GPIO.OUT)
INFO:     Started server process [2273]
INFO:uvicorn.error:Started server process [2273]
INFO:     Waiting for application startup.
INFO:uvicorn.error:Waiting for application startup.
INFO:     Application startup complete.
INFO:uvicorn.error:Application startup complete.
(132974295602273990883125803057749735904588330990273298165652963719803103331338066224736047259670794690360464313866494270056928121602265010022594322678942904952265758311149630141351127532640392647397911003488284847587816623925391551005670722789709816330187399538115137166513028607995609621106021994838514708117, 10215636925397142776245256898380230542584179652686351003791624400273636359771288415804136972192345722374345459074869078741666462602305310615680948140613319)
INFO:     10.20.40.10:0 - "GET /getMonths_images HTTP/1.1" 200 OK
INFO:     10.20.40.10:0 - "GET /login HTTP/1.1" 200 OK
DEBUG:multipart.multipart:Calling on_field_start with no data
DEBUG:multipart.multipart:Calling on_field_name with data[0:3]
DEBUG:multipart.multipart:Calling on_field_data with data[4:22]
DEBUG:multipart.multipart:Calling on_field_end with no data
DEBUG:multipart.multipart:Calling on_end with no data
INFO:     10.20.40.10:0 - "POST /getToken HTTP/1.1" 200 OK
INFO:     10.20.40.10:0 - "GET / HTTP/1.1" 500 Internal Server Error
ERROR:    Exception in ASGI application
Traceback (most recent call last):
  File "/usr/local/lib/python3.7/dist-packages/uvicorn/protocols/http/httptools_impl.py", line 375, in run_asgi
    result = await app(self.scope, self.receive, self.send)
  File "/usr/local/lib/python3.7/dist-packages/uvicorn/middleware/proxy_headers.py", line 75, in __call__
    return await self.app(scope, receive, send)
  File "/usr/local/lib/python3.7/dist-packages/fastapi/applications.py", line 208, in __call__
    await super().__call__(scope, receive, send)
  File "/usr/local/lib/python3.7/dist-packages/starlette/applications.py", line 112, in __call__
    await self.middleware_stack(scope, receive, send)
  File "/usr/local/lib/python3.7/dist-packages/starlette/middleware/errors.py", line 181, in __call__
    raise exc
  File "/usr/local/lib/python3.7/dist-packages/starlette/middleware/errors.py", line 159, in __call__
    await self.app(scope, receive, _send)
  File "/usr/local/lib/python3.7/dist-packages/starlette/exceptions.py", line 82, in __call__
    raise exc
  File "/usr/local/lib/python3.7/dist-packages/starlette/exceptions.py", line 71, in __call__
    await self.app(scope, receive, sender)
  File "/usr/local/lib/python3.7/dist-packages/starlette/routing.py", line 656, in __call__
    await route.handle(scope, receive, send)
  File "/usr/local/lib/python3.7/dist-packages/starlette/routing.py", line 259, in handle
    await self.app(scope, receive, send)
  File "/usr/local/lib/python3.7/dist-packages/starlette/routing.py", line 61, in app
    response = await func(request)
  File "/usr/local/lib/python3.7/dist-packages/fastapi/routing.py", line 227, in app
    dependant=dependant, values=values, is_coroutine=is_coroutine
  File "/usr/local/lib/python3.7/dist-packages/fastapi/routing.py", line 161, in run_endpoint_function
    return await run_in_threadpool(dependant.call, **values)
  File "/usr/local/lib/python3.7/dist-packages/starlette/concurrency.py", line 39, in run_in_threadpool
    return await anyio.to_thread.run_sync(func, *args)
  File "/usr/local/lib/python3.7/dist-packages/anyio/to_thread.py", line 29, in run_sync
    limiter=limiter)
  File "/usr/local/lib/python3.7/dist-packages/anyio/_backends/_asyncio.py", line 818, in run_sync_in_worker_thread
    return await future
  File "/usr/local/lib/python3.7/dist-packages/anyio/_backends/_asyncio.py", line 754, in run
    result = context.run(func, *args)
  File "./main.py", line 43, in index
    f = open("./client/index.html","r")
FileNotFoundError: [Errno 2] No such file or directory: './client/index.html'
ERROR:uvicorn.error:Exception in ASGI application
Traceback (most recent call last):
  File "/usr/local/lib/python3.7/dist-packages/uvicorn/protocols/http/httptools_impl.py", line 375, in run_asgi
    result = await app(self.scope, self.receive, self.send)
  File "/usr/local/lib/python3.7/dist-packages/uvicorn/middleware/proxy_headers.py", line 75, in __call__
    return await self.app(scope, receive, send)
  File "/usr/local/lib/python3.7/dist-packages/fastapi/applications.py", line 208, in __call__
    await super().__call__(scope, receive, send)
  File "/usr/local/lib/python3.7/dist-packages/starlette/applications.py", line 112, in __call__
    await self.middleware_stack(scope, receive, send)
  File "/usr/local/lib/python3.7/dist-packages/starlette/middleware/errors.py", line 181, in __call__
    raise exc
  File "/usr/local/lib/python3.7/dist-packages/starlette/middleware/errors.py", line 159, in __call__
    await self.app(scope, receive, _send)
  File "/usr/local/lib/python3.7/dist-packages/starlette/exceptions.py", line 82, in __call__
    raise exc
  File "/usr/local/lib/python3.7/dist-packages/starlette/exceptions.py", line 71, in __call__
    await self.app(scope, receive, sender)
  File "/usr/local/lib/python3.7/dist-packages/starlette/routing.py", line 656, in __call__
    await route.handle(scope, receive, send)
  File "/usr/local/lib/python3.7/dist-packages/starlette/routing.py", line 259, in handle
    await self.app(scope, receive, send)
  File "/usr/local/lib/python3.7/dist-packages/starlette/routing.py", line 61, in app
    response = await func(request)
  File "/usr/local/lib/python3.7/dist-packages/fastapi/routing.py", line 227, in app
    dependant=dependant, values=values, is_coroutine=is_coroutine
  File "/usr/local/lib/python3.7/dist-packages/fastapi/routing.py", line 161, in run_endpoint_function
    return await run_in_threadpool(dependant.call, **values)
  File "/usr/local/lib/python3.7/dist-packages/starlette/concurrency.py", line 39, in run_in_threadpool
    return await anyio.to_thread.run_sync(func, *args)
  File "/usr/local/lib/python3.7/dist-packages/anyio/to_thread.py", line 29, in run_sync
    limiter=limiter)
  File "/usr/local/lib/python3.7/dist-packages/anyio/_backends/_asyncio.py", line 818, in run_sync_in_worker_thread
    return await future
  File "/usr/local/lib/python3.7/dist-packages/anyio/_backends/_asyncio.py", line 754, in run
    result = context.run(func, *args)
  File "./main.py", line 43, in index
    f = open("./client/index.html","r")
FileNotFoundError: [Errno 2] No such file or directory: './client/index.html'
INFO:     10.20.40.10:0 - "GET / HTTP/1.1" 500 Internal Server Error
ERROR:    Exception in ASGI application
Traceback (most recent call last):
  File "/usr/local/lib/python3.7/dist-packages/uvicorn/protocols/http/httptools_impl.py", line 375, in run_asgi
    result = await app(self.scope, self.receive, self.send)
  File "/usr/local/lib/python3.7/dist-packages/uvicorn/middleware/proxy_headers.py", line 75, in __call__
    return await self.app(scope, receive, send)
  File "/usr/local/lib/python3.7/dist-packages/fastapi/applications.py", line 208, in __call__
    await super().__call__(scope, receive, send)
  File "/usr/local/lib/python3.7/dist-packages/starlette/applications.py", line 112, in __call__
    await self.middleware_stack(scope, receive, send)
  File "/usr/local/lib/python3.7/dist-packages/starlette/middleware/errors.py", line 181, in __call__
    raise exc
  File "/usr/local/lib/python3.7/dist-packages/starlette/middleware/errors.py", line 159, in __call__
    await self.app(scope, receive, _send)
  File "/usr/local/lib/python3.7/dist-packages/starlette/exceptions.py", line 82, in __call__
    raise exc
  File "/usr/local/lib/python3.7/dist-packages/starlette/exceptions.py", line 71, in __call__
    await self.app(scope, receive, sender)
  File "/usr/local/lib/python3.7/dist-packages/starlette/routing.py", line 656, in __call__
    await route.handle(scope, receive, send)
  File "/usr/local/lib/python3.7/dist-packages/starlette/routing.py", line 259, in handle
    await self.app(scope, receive, send)
  File "/usr/local/lib/python3.7/dist-packages/starlette/routing.py", line 61, in app
    response = await func(request)
  File "/usr/local/lib/python3.7/dist-packages/fastapi/routing.py", line 227, in app
    dependant=dependant, values=values, is_coroutine=is_coroutine
  File "/usr/local/lib/python3.7/dist-packages/fastapi/routing.py", line 161, in run_endpoint_function
    return await run_in_threadpool(dependant.call, **values)
  File "/usr/local/lib/python3.7/dist-packages/starlette/concurrency.py", line 39, in run_in_threadpool
    return await anyio.to_thread.run_sync(func, *args)
  File "/usr/local/lib/python3.7/dist-packages/anyio/to_thread.py", line 29, in run_sync
    limiter=limiter)
  File "/usr/local/lib/python3.7/dist-packages/anyio/_backends/_asyncio.py", line 818, in run_sync_in_worker_thread
    return await future
  File "/usr/local/lib/python3.7/dist-packages/anyio/_backends/_asyncio.py", line 754, in run
    result = context.run(func, *args)
  File "./main.py", line 43, in index
    f = open("./client/index.html","r")
FileNotFoundError: [Errno 2] No such file or directory: './client/index.html'
ERROR:uvicorn.error:Exception in ASGI application
Traceback (most recent call last):
  File "/usr/local/lib/python3.7/dist-packages/uvicorn/protocols/http/httptools_impl.py", line 375, in run_asgi
    result = await app(self.scope, self.receive, self.send)
  File "/usr/local/lib/python3.7/dist-packages/uvicorn/middleware/proxy_headers.py", line 75, in __call__
    return await self.app(scope, receive, send)
  File "/usr/local/lib/python3.7/dist-packages/fastapi/applications.py", line 208, in __call__
    await super().__call__(scope, receive, send)
  File "/usr/local/lib/python3.7/dist-packages/starlette/applications.py", line 112, in __call__
    await self.middleware_stack(scope, receive, send)
  File "/usr/local/lib/python3.7/dist-packages/starlette/middleware/errors.py", line 181, in __call__
    raise exc
  File "/usr/local/lib/python3.7/dist-packages/starlette/middleware/errors.py", line 159, in __call__
    await self.app(scope, receive, _send)
  File "/usr/local/lib/python3.7/dist-packages/starlette/exceptions.py", line 82, in __call__
    raise exc
  File "/usr/local/lib/python3.7/dist-packages/starlette/exceptions.py", line 71, in __call__
    await self.app(scope, receive, sender)
  File "/usr/local/lib/python3.7/dist-packages/starlette/routing.py", line 656, in __call__
    await route.handle(scope, receive, send)
  File "/usr/local/lib/python3.7/dist-packages/starlette/routing.py", line 259, in handle
    await self.app(scope, receive, send)
  File "/usr/local/lib/python3.7/dist-packages/starlette/routing.py", line 61, in app
    response = await func(request)
  File "/usr/local/lib/python3.7/dist-packages/fastapi/routing.py", line 227, in app
    dependant=dependant, values=values, is_coroutine=is_coroutine
  File "/usr/local/lib/python3.7/dist-packages/fastapi/routing.py", line 161, in run_endpoint_function
    return await run_in_threadpool(dependant.call, **values)
  File "/usr/local/lib/python3.7/dist-packages/starlette/concurrency.py", line 39, in run_in_threadpool
    return await anyio.to_thread.run_sync(func, *args)
  File "/usr/local/lib/python3.7/dist-packages/anyio/to_thread.py", line 29, in run_sync
    limiter=limiter)
  File "/usr/local/lib/python3.7/dist-packages/anyio/_backends/_asyncio.py", line 818, in run_sync_in_worker_thread
    return await future
  File "/usr/local/lib/python3.7/dist-packages/anyio/_backends/_asyncio.py", line 754, in run
    result = context.run(func, *args)
  File "./main.py", line 43, in index
    f = open("./client/index.html","r")
FileNotFoundError: [Errno 2] No such file or directory: './client/index.html'
WARNING:  WatchGodReload detected file change in '['/root/IT3530-Project/server/main.py']'. Reloading...
INFO:     Shutting down
INFO:uvicorn.error:Shutting down
INFO:     Waiting for application shutdown.
INFO:uvicorn.error:Waiting for application shutdown.
INFO:     Application shutdown complete.
INFO:uvicorn.error:Application shutdown complete.
INFO:     Finished server process [2273]
INFO:uvicorn.error:Finished server process [2273]
./main.py:9: RuntimeWarning: This channel is already in use, continuing anyway.  Use GPIO.setwarnings(False) to disable warnings.
  GPIO.setup(20, GPIO.OUT)
INFO:     Started server process [2284]
INFO:uvicorn.error:Started server process [2284]
INFO:     Waiting for application startup.
INFO:uvicorn.error:Waiting for application startup.
INFO:     Application startup complete.
INFO:uvicorn.error:Application startup complete.
INFO:     10.20.40.10:0 - "GET / HTTP/1.1" 500 Internal Server Error
ERROR:    Exception in ASGI application
Traceback (most recent call last):
  File "/usr/local/lib/python3.7/dist-packages/uvicorn/protocols/http/httptools_impl.py", line 375, in run_asgi
    result = await app(self.scope, self.receive, self.send)
  File "/usr/local/lib/python3.7/dist-packages/uvicorn/middleware/proxy_headers.py", line 75, in __call__
    return await self.app(scope, receive, send)
  File "/usr/local/lib/python3.7/dist-packages/fastapi/applications.py", line 208, in __call__
    await super().__call__(scope, receive, send)
  File "/usr/local/lib/python3.7/dist-packages/starlette/applications.py", line 112, in __call__
    await self.middleware_stack(scope, receive, send)
  File "/usr/local/lib/python3.7/dist-packages/starlette/middleware/errors.py", line 181, in __call__
    raise exc
  File "/usr/local/lib/python3.7/dist-packages/starlette/middleware/errors.py", line 159, in __call__
    await self.app(scope, receive, _send)
  File "/usr/local/lib/python3.7/dist-packages/starlette/exceptions.py", line 82, in __call__
    raise exc
  File "/usr/local/lib/python3.7/dist-packages/starlette/exceptions.py", line 71, in __call__
    await self.app(scope, receive, sender)
  File "/usr/local/lib/python3.7/dist-packages/starlette/routing.py", line 656, in __call__
    await route.handle(scope, receive, send)
  File "/usr/local/lib/python3.7/dist-packages/starlette/routing.py", line 259, in handle
    await self.app(scope, receive, send)
  File "/usr/local/lib/python3.7/dist-packages/starlette/routing.py", line 61, in app
    response = await func(request)
  File "/usr/local/lib/python3.7/dist-packages/fastapi/routing.py", line 227, in app
    dependant=dependant, values=values, is_coroutine=is_coroutine
  File "/usr/local/lib/python3.7/dist-packages/fastapi/routing.py", line 161, in run_endpoint_function
    return await run_in_threadpool(dependant.call, **values)
  File "/usr/local/lib/python3.7/dist-packages/starlette/concurrency.py", line 39, in run_in_threadpool
    return await anyio.to_thread.run_sync(func, *args)
  File "/usr/local/lib/python3.7/dist-packages/anyio/to_thread.py", line 29, in run_sync
    limiter=limiter)
  File "/usr/local/lib/python3.7/dist-packages/anyio/_backends/_asyncio.py", line 818, in run_sync_in_worker_thread
    return await future
  File "/usr/local/lib/python3.7/dist-packages/anyio/_backends/_asyncio.py", line 754, in run
    result = context.run(func, *args)
  File "./main.py", line 43, in index
    f = open("./client/index.html","r")
FileNotFoundError: [Errno 2] No such file or directory: './client/index.html'
ERROR:uvicorn.error:Exception in ASGI application
Traceback (most recent call last):
  File "/usr/local/lib/python3.7/dist-packages/uvicorn/protocols/http/httptools_impl.py", line 375, in run_asgi
    result = await app(self.scope, self.receive, self.send)
  File "/usr/local/lib/python3.7/dist-packages/uvicorn/middleware/proxy_headers.py", line 75, in __call__
    return await self.app(scope, receive, send)
  File "/usr/local/lib/python3.7/dist-packages/fastapi/applications.py", line 208, in __call__
    await super().__call__(scope, receive, send)
  File "/usr/local/lib/python3.7/dist-packages/starlette/applications.py", line 112, in __call__
    await self.middleware_stack(scope, receive, send)
  File "/usr/local/lib/python3.7/dist-packages/starlette/middleware/errors.py", line 181, in __call__
    raise exc
  File "/usr/local/lib/python3.7/dist-packages/starlette/middleware/errors.py", line 159, in __call__
    await self.app(scope, receive, _send)
  File "/usr/local/lib/python3.7/dist-packages/starlette/exceptions.py", line 82, in __call__
    raise exc
  File "/usr/local/lib/python3.7/dist-packages/starlette/exceptions.py", line 71, in __call__
    await self.app(scope, receive, sender)
  File "/usr/local/lib/python3.7/dist-packages/starlette/routing.py", line 656, in __call__
    await route.handle(scope, receive, send)
  File "/usr/local/lib/python3.7/dist-packages/starlette/routing.py", line 259, in handle
    await self.app(scope, receive, send)
  File "/usr/local/lib/python3.7/dist-packages/starlette/routing.py", line 61, in app
    response = await func(request)
  File "/usr/local/lib/python3.7/dist-packages/fastapi/routing.py", line 227, in app
    dependant=dependant, values=values, is_coroutine=is_coroutine
  File "/usr/local/lib/python3.7/dist-packages/fastapi/routing.py", line 161, in run_endpoint_function
    return await run_in_threadpool(dependant.call, **values)
  File "/usr/local/lib/python3.7/dist-packages/starlette/concurrency.py", line 39, in run_in_threadpool
    return await anyio.to_thread.run_sync(func, *args)
  File "/usr/local/lib/python3.7/dist-packages/anyio/to_thread.py", line 29, in run_sync
    limiter=limiter)
  File "/usr/local/lib/python3.7/dist-packages/anyio/_backends/_asyncio.py", line 818, in run_sync_in_worker_thread
    return await future
  File "/usr/local/lib/python3.7/dist-packages/anyio/_backends/_asyncio.py", line 754, in run
    result = context.run(func, *args)
  File "./main.py", line 43, in index
    f = open("./client/index.html","r")
FileNotFoundError: [Errno 2] No such file or directory: './client/index.html'
DEBUG:multipart.multipart:Calling on_field_start with no data
DEBUG:multipart.multipart:Calling on_field_name with data[0:3]
DEBUG:multipart.multipart:Calling on_field_data with data[4:22]
DEBUG:multipart.multipart:Calling on_field_end with no data
DEBUG:multipart.multipart:Calling on_end with no data
INFO:     10.20.40.10:0 - "POST /getToken HTTP/1.1" 200 OK
INFO:     10.20.40.10:0 - "GET / HTTP/1.1" 500 Internal Server Error
ERROR:    Exception in ASGI application
Traceback (most recent call last):
  File "/usr/local/lib/python3.7/dist-packages/uvicorn/protocols/http/httptools_impl.py", line 375, in run_asgi
    result = await app(self.scope, self.receive, self.send)
  File "/usr/local/lib/python3.7/dist-packages/uvicorn/middleware/proxy_headers.py", line 75, in __call__
    return await self.app(scope, receive, send)
  File "/usr/local/lib/python3.7/dist-packages/fastapi/applications.py", line 208, in __call__
    await super().__call__(scope, receive, send)
  File "/usr/local/lib/python3.7/dist-packages/starlette/applications.py", line 112, in __call__
    await self.middleware_stack(scope, receive, send)
  File "/usr/local/lib/python3.7/dist-packages/starlette/middleware/errors.py", line 181, in __call__
    raise exc
  File "/usr/local/lib/python3.7/dist-packages/starlette/middleware/errors.py", line 159, in __call__
    await self.app(scope, receive, _send)
  File "/usr/local/lib/python3.7/dist-packages/starlette/exceptions.py", line 82, in __call__
    raise exc
  File "/usr/local/lib/python3.7/dist-packages/starlette/exceptions.py", line 71, in __call__
    await self.app(scope, receive, sender)
  File "/usr/local/lib/python3.7/dist-packages/starlette/routing.py", line 656, in __call__
    await route.handle(scope, receive, send)
  File "/usr/local/lib/python3.7/dist-packages/starlette/routing.py", line 259, in handle
    await self.app(scope, receive, send)
  File "/usr/local/lib/python3.7/dist-packages/starlette/routing.py", line 61, in app
    response = await func(request)
  File "/usr/local/lib/python3.7/dist-packages/fastapi/routing.py", line 227, in app
    dependant=dependant, values=values, is_coroutine=is_coroutine
  File "/usr/local/lib/python3.7/dist-packages/fastapi/routing.py", line 161, in run_endpoint_function
    return await run_in_threadpool(dependant.call, **values)
  File "/usr/local/lib/python3.7/dist-packages/starlette/concurrency.py", line 39, in run_in_threadpool
    return await anyio.to_thread.run_sync(func, *args)
  File "/usr/local/lib/python3.7/dist-packages/anyio/to_thread.py", line 29, in run_sync
    limiter=limiter)
  File "/usr/local/lib/python3.7/dist-packages/anyio/_backends/_asyncio.py", line 818, in run_sync_in_worker_thread
    return await future
  File "/usr/local/lib/python3.7/dist-packages/anyio/_backends/_asyncio.py", line 754, in run
    result = context.run(func, *args)
  File "./main.py", line 43, in index
    f = open("./client/index.html","r")
FileNotFoundError: [Errno 2] No such file or directory: './client/index.html'
ERROR:uvicorn.error:Exception in ASGI application
Traceback (most recent call last):
  File "/usr/local/lib/python3.7/dist-packages/uvicorn/protocols/http/httptools_impl.py", line 375, in run_asgi
    result = await app(self.scope, self.receive, self.send)
  File "/usr/local/lib/python3.7/dist-packages/uvicorn/middleware/proxy_headers.py", line 75, in __call__
    return await self.app(scope, receive, send)
  File "/usr/local/lib/python3.7/dist-packages/fastapi/applications.py", line 208, in __call__
    await super().__call__(scope, receive, send)
  File "/usr/local/lib/python3.7/dist-packages/starlette/applications.py", line 112, in __call__
    await self.middleware_stack(scope, receive, send)
  File "/usr/local/lib/python3.7/dist-packages/starlette/middleware/errors.py", line 181, in __call__
    raise exc
  File "/usr/local/lib/python3.7/dist-packages/starlette/middleware/errors.py", line 159, in __call__
    await self.app(scope, receive, _send)
  File "/usr/local/lib/python3.7/dist-packages/starlette/exceptions.py", line 82, in __call__
    raise exc
  File "/usr/local/lib/python3.7/dist-packages/starlette/exceptions.py", line 71, in __call__
    await self.app(scope, receive, sender)
  File "/usr/local/lib/python3.7/dist-packages/starlette/routing.py", line 656, in __call__
    await route.handle(scope, receive, send)
  File "/usr/local/lib/python3.7/dist-packages/starlette/routing.py", line 259, in handle
    await self.app(scope, receive, send)
  File "/usr/local/lib/python3.7/dist-packages/starlette/routing.py", line 61, in app
    response = await func(request)
  File "/usr/local/lib/python3.7/dist-packages/fastapi/routing.py", line 227, in app
    dependant=dependant, values=values, is_coroutine=is_coroutine
  File "/usr/local/lib/python3.7/dist-packages/fastapi/routing.py", line 161, in run_endpoint_function
    return await run_in_threadpool(dependant.call, **values)
  File "/usr/local/lib/python3.7/dist-packages/starlette/concurrency.py", line 39, in run_in_threadpool
    return await anyio.to_thread.run_sync(func, *args)
  File "/usr/local/lib/python3.7/dist-packages/anyio/to_thread.py", line 29, in run_sync
    limiter=limiter)
  File "/usr/local/lib/python3.7/dist-packages/anyio/_backends/_asyncio.py", line 818, in run_sync_in_worker_thread
    return await future
  File "/usr/local/lib/python3.7/dist-packages/anyio/_backends/_asyncio.py", line 754, in run
    result = context.run(func, *args)
  File "./main.py", line 43, in index
    f = open("./client/index.html","r")
FileNotFoundError: [Errno 2] No such file or directory: './client/index.html'
INFO:     10.20.40.10:0 - "GET / HTTP/1.1" 500 Internal Server Error
ERROR:    Exception in ASGI application
Traceback (most recent call last):
  File "/usr/local/lib/python3.7/dist-packages/uvicorn/protocols/http/httptools_impl.py", line 375, in run_asgi
    result = await app(self.scope, self.receive, self.send)
  File "/usr/local/lib/python3.7/dist-packages/uvicorn/middleware/proxy_headers.py", line 75, in __call__
    return await self.app(scope, receive, send)
  File "/usr/local/lib/python3.7/dist-packages/fastapi/applications.py", line 208, in __call__
    await super().__call__(scope, receive, send)
  File "/usr/local/lib/python3.7/dist-packages/starlette/applications.py", line 112, in __call__
    await self.middleware_stack(scope, receive, send)
  File "/usr/local/lib/python3.7/dist-packages/starlette/middleware/errors.py", line 181, in __call__
    raise exc
  File "/usr/local/lib/python3.7/dist-packages/starlette/middleware/errors.py", line 159, in __call__
    await self.app(scope, receive, _send)
  File "/usr/local/lib/python3.7/dist-packages/starlette/exceptions.py", line 82, in __call__
    raise exc
  File "/usr/local/lib/python3.7/dist-packages/starlette/exceptions.py", line 71, in __call__
    await self.app(scope, receive, sender)
  File "/usr/local/lib/python3.7/dist-packages/starlette/routing.py", line 656, in __call__
    await route.handle(scope, receive, send)
  File "/usr/local/lib/python3.7/dist-packages/starlette/routing.py", line 259, in handle
    await self.app(scope, receive, send)
  File "/usr/local/lib/python3.7/dist-packages/starlette/routing.py", line 61, in app
    response = await func(request)
  File "/usr/local/lib/python3.7/dist-packages/fastapi/routing.py", line 227, in app
    dependant=dependant, values=values, is_coroutine=is_coroutine
  File "/usr/local/lib/python3.7/dist-packages/fastapi/routing.py", line 161, in run_endpoint_function
    return await run_in_threadpool(dependant.call, **values)
  File "/usr/local/lib/python3.7/dist-packages/starlette/concurrency.py", line 39, in run_in_threadpool
    return await anyio.to_thread.run_sync(func, *args)
  File "/usr/local/lib/python3.7/dist-packages/anyio/to_thread.py", line 29, in run_sync
    limiter=limiter)
  File "/usr/local/lib/python3.7/dist-packages/anyio/_backends/_asyncio.py", line 818, in run_sync_in_worker_thread
    return await future
  File "/usr/local/lib/python3.7/dist-packages/anyio/_backends/_asyncio.py", line 754, in run
    result = context.run(func, *args)
  File "./main.py", line 43, in index
    f = open("./client/index.html","r")
FileNotFoundError: [Errno 2] No such file or directory: './client/index.html'
ERROR:uvicorn.error:Exception in ASGI application
Traceback (most recent call last):
  File "/usr/local/lib/python3.7/dist-packages/uvicorn/protocols/http/httptools_impl.py", line 375, in run_asgi
    result = await app(self.scope, self.receive, self.send)
  File "/usr/local/lib/python3.7/dist-packages/uvicorn/middleware/proxy_headers.py", line 75, in __call__
    return await self.app(scope, receive, send)
  File "/usr/local/lib/python3.7/dist-packages/fastapi/applications.py", line 208, in __call__
    await super().__call__(scope, receive, send)
  File "/usr/local/lib/python3.7/dist-packages/starlette/applications.py", line 112, in __call__
    await self.middleware_stack(scope, receive, send)
  File "/usr/local/lib/python3.7/dist-packages/starlette/middleware/errors.py", line 181, in __call__
    raise exc
  File "/usr/local/lib/python3.7/dist-packages/starlette/middleware/errors.py", line 159, in __call__
    await self.app(scope, receive, _send)
  File "/usr/local/lib/python3.7/dist-packages/starlette/exceptions.py", line 82, in __call__
    raise exc
  File "/usr/local/lib/python3.7/dist-packages/starlette/exceptions.py", line 71, in __call__
    await self.app(scope, receive, sender)
  File "/usr/local/lib/python3.7/dist-packages/starlette/routing.py", line 656, in __call__
    await route.handle(scope, receive, send)
  File "/usr/local/lib/python3.7/dist-packages/starlette/routing.py", line 259, in handle
    await self.app(scope, receive, send)
  File "/usr/local/lib/python3.7/dist-packages/starlette/routing.py", line 61, in app
    response = await func(request)
  File "/usr/local/lib/python3.7/dist-packages/fastapi/routing.py", line 227, in app
    dependant=dependant, values=values, is_coroutine=is_coroutine
  File "/usr/local/lib/python3.7/dist-packages/fastapi/routing.py", line 161, in run_endpoint_function
    return await run_in_threadpool(dependant.call, **values)
  File "/usr/local/lib/python3.7/dist-packages/starlette/concurrency.py", line 39, in run_in_threadpool
    return await anyio.to_thread.run_sync(func, *args)
  File "/usr/local/lib/python3.7/dist-packages/anyio/to_thread.py", line 29, in run_sync
    limiter=limiter)
  File "/usr/local/lib/python3.7/dist-packages/anyio/_backends/_asyncio.py", line 818, in run_sync_in_worker_thread
    return await future
  File "/usr/local/lib/python3.7/dist-packages/anyio/_backends/_asyncio.py", line 754, in run
    result = context.run(func, *args)
  File "./main.py", line 43, in index
    f = open("./client/index.html","r")
FileNotFoundError: [Errno 2] No such file or directory: './client/index.html'
INFO:     10.20.40.10:0 - "GET /login HTTP/1.1" 200 OK
DEBUG:multipart.multipart:Calling on_field_start with no data
DEBUG:multipart.multipart:Calling on_field_name with data[0:3]
DEBUG:multipart.multipart:Calling on_field_data with data[4:22]
DEBUG:multipart.multipart:Calling on_field_end with no data
DEBUG:multipart.multipart:Calling on_end with no data
INFO:     10.20.40.10:0 - "POST /getToken HTTP/1.1" 200 OK
WARNING:  WatchGodReload detected file change in '['/root/IT3530-Project/server/main.py']'. Reloading...
INFO:     Shutting down
INFO:uvicorn.error:Shutting down
INFO:     Waiting for application shutdown.
INFO:uvicorn.error:Waiting for application shutdown.
INFO:     Application shutdown complete.
INFO:uvicorn.error:Application shutdown complete.
INFO:     Finished server process [2284]
INFO:uvicorn.error:Finished server process [2284]
./main.py:9: RuntimeWarning: This channel is already in use, continuing anyway.  Use GPIO.setwarnings(False) to disable warnings.
  GPIO.setup(20, GPIO.OUT)
INFO:     Started server process [2340]
INFO:uvicorn.error:Started server process [2340]
INFO:     Waiting for application startup.
INFO:uvicorn.error:Waiting for application startup.
INFO:     Application startup complete.
INFO:uvicorn.error:Application startup complete.
DEBUG:multipart.multipart:Calling on_field_start with no data
DEBUG:multipart.multipart:Calling on_field_name with data[0:3]
DEBUG:multipart.multipart:Calling on_field_data with data[4:22]
DEBUG:multipart.multipart:Calling on_field_end with no data
DEBUG:multipart.multipart:Calling on_end with no data
INFO:     10.20.41.203:0 - "POST /getToken HTTP/1.1" 200 OK
INFO:     10.20.41.203:0 - "GET /getMonths HTTP/1.1" 404 Not Found
INFO:     10.20.41.203:0 - "GET /getMonths_image HTTP/1.1" 404 Not Found
INFO:     10.20.41.203:0 - "GET /getMonths_image HTTP/1.1" 404 Not Found
INFO:     10.20.41.203:0 - "GET /getMonths_images HTTP/1.1" 200 OK
WARNING:  WatchGodReload detected file change in '['/root/IT3530-Project/server/main.py']'. Reloading...
INFO:     Shutting down
INFO:uvicorn.error:Shutting down
INFO:     Waiting for application shutdown.
INFO:uvicorn.error:Waiting for application shutdown.
INFO:     Application shutdown complete.
INFO:uvicorn.error:Application shutdown complete.
INFO:     Finished server process [2340]
INFO:uvicorn.error:Finished server process [2340]
./main.py:9: RuntimeWarning: This channel is already in use, continuing anyway.  Use GPIO.setwarnings(False) to disable warnings.
  GPIO.setup(20, GPIO.OUT)
INFO:     Started server process [2385]
INFO:uvicorn.error:Started server process [2385]
INFO:     Waiting for application startup.
INFO:uvicorn.error:Waiting for application startup.
INFO:     Application startup complete.
INFO:uvicorn.error:Application startup complete.
INFO:     10.20.40.10:0 - "GET /getMonths_images HTTP/1.1" 500 Internal Server Error
ERROR:    Exception in ASGI application
Traceback (most recent call last):
  File "/usr/local/lib/python3.7/dist-packages/uvicorn/protocols/http/httptools_impl.py", line 375, in run_asgi
    result = await app(self.scope, self.receive, self.send)
  File "/usr/local/lib/python3.7/dist-packages/uvicorn/middleware/proxy_headers.py", line 75, in __call__
    return await self.app(scope, receive, send)
  File "/usr/local/lib/python3.7/dist-packages/fastapi/applications.py", line 208, in __call__
    await super().__call__(scope, receive, send)
  File "/usr/local/lib/python3.7/dist-packages/starlette/applications.py", line 112, in __call__
    await self.middleware_stack(scope, receive, send)
  File "/usr/local/lib/python3.7/dist-packages/starlette/middleware/errors.py", line 181, in __call__
    raise exc
  File "/usr/local/lib/python3.7/dist-packages/starlette/middleware/errors.py", line 159, in __call__
    await self.app(scope, receive, _send)
  File "/usr/local/lib/python3.7/dist-packages/starlette/exceptions.py", line 82, in __call__
    raise exc
  File "/usr/local/lib/python3.7/dist-packages/starlette/exceptions.py", line 71, in __call__
    await self.app(scope, receive, sender)
  File "/usr/local/lib/python3.7/dist-packages/starlette/routing.py", line 656, in __call__
    await route.handle(scope, receive, send)
  File "/usr/local/lib/python3.7/dist-packages/starlette/routing.py", line 259, in handle
    await self.app(scope, receive, send)
  File "/usr/local/lib/python3.7/dist-packages/starlette/routing.py", line 61, in app
    response = await func(request)
  File "/usr/local/lib/python3.7/dist-packages/fastapi/routing.py", line 227, in app
    dependant=dependant, values=values, is_coroutine=is_coroutine
  File "/usr/local/lib/python3.7/dist-packages/fastapi/routing.py", line 161, in run_endpoint_function
    return await run_in_threadpool(dependant.call, **values)
  File "/usr/local/lib/python3.7/dist-packages/starlette/concurrency.py", line 39, in run_in_threadpool
    return await anyio.to_thread.run_sync(func, *args)
  File "/usr/local/lib/python3.7/dist-packages/anyio/to_thread.py", line 29, in run_sync
    limiter=limiter)
  File "/usr/local/lib/python3.7/dist-packages/anyio/_backends/_asyncio.py", line 818, in run_sync_in_worker_thread
    return await future
  File "/usr/local/lib/python3.7/dist-packages/anyio/_backends/_asyncio.py", line 754, in run
    result = context.run(func, *args)
  File "./main.py", line 54, in read_root
    ls = os.listdir("../images")
FileNotFoundError: [Errno 2] No such file or directory: '../images'
ERROR:uvicorn.error:Exception in ASGI application
Traceback (most recent call last):
  File "/usr/local/lib/python3.7/dist-packages/uvicorn/protocols/http/httptools_impl.py", line 375, in run_asgi
    result = await app(self.scope, self.receive, self.send)
  File "/usr/local/lib/python3.7/dist-packages/uvicorn/middleware/proxy_headers.py", line 75, in __call__
    return await self.app(scope, receive, send)
  File "/usr/local/lib/python3.7/dist-packages/fastapi/applications.py", line 208, in __call__
    await super().__call__(scope, receive, send)
  File "/usr/local/lib/python3.7/dist-packages/starlette/applications.py", line 112, in __call__
    await self.middleware_stack(scope, receive, send)
  File "/usr/local/lib/python3.7/dist-packages/starlette/middleware/errors.py", line 181, in __call__
    raise exc
  File "/usr/local/lib/python3.7/dist-packages/starlette/middleware/errors.py", line 159, in __call__
    await self.app(scope, receive, _send)
  File "/usr/local/lib/python3.7/dist-packages/starlette/exceptions.py", line 82, in __call__
    raise exc
  File "/usr/local/lib/python3.7/dist-packages/starlette/exceptions.py", line 71, in __call__
    await self.app(scope, receive, sender)
  File "/usr/local/lib/python3.7/dist-packages/starlette/routing.py", line 656, in __call__
    await route.handle(scope, receive, send)
  File "/usr/local/lib/python3.7/dist-packages/starlette/routing.py", line 259, in handle
    await self.app(scope, receive, send)
  File "/usr/local/lib/python3.7/dist-packages/starlette/routing.py", line 61, in app
    response = await func(request)
  File "/usr/local/lib/python3.7/dist-packages/fastapi/routing.py", line 227, in app
    dependant=dependant, values=values, is_coroutine=is_coroutine
  File "/usr/local/lib/python3.7/dist-packages/fastapi/routing.py", line 161, in run_endpoint_function
    return await run_in_threadpool(dependant.call, **values)
  File "/usr/local/lib/python3.7/dist-packages/starlette/concurrency.py", line 39, in run_in_threadpool
    return await anyio.to_thread.run_sync(func, *args)
  File "/usr/local/lib/python3.7/dist-packages/anyio/to_thread.py", line 29, in run_sync
    limiter=limiter)
  File "/usr/local/lib/python3.7/dist-packages/anyio/_backends/_asyncio.py", line 818, in run_sync_in_worker_thread
    return await future
  File "/usr/local/lib/python3.7/dist-packages/anyio/_backends/_asyncio.py", line 754, in run
    result = context.run(func, *args)
  File "./main.py", line 54, in read_root
    ls = os.listdir("../images")
FileNotFoundError: [Errno 2] No such file or directory: '../images'
WARNING:  WatchGodReload detected file change in '['/root/IT3530-Project/server/main.py']'. Reloading...
INFO:     Shutting down
INFO:uvicorn.error:Shutting down
INFO:     Waiting for application shutdown.
INFO:uvicorn.error:Waiting for application shutdown.
INFO:     Application shutdown complete.
INFO:uvicorn.error:Application shutdown complete.
INFO:     Finished server process [2385]
INFO:uvicorn.error:Finished server process [2385]
./main.py:9: RuntimeWarning: This channel is already in use, continuing anyway.  Use GPIO.setwarnings(False) to disable warnings.
  GPIO.setup(20, GPIO.OUT)
INFO:     Started server process [2412]
INFO:uvicorn.error:Started server process [2412]
INFO:     Waiting for application startup.
INFO:uvicorn.error:Waiting for application startup.
INFO:     Application startup complete.
INFO:uvicorn.error:Application startup complete.
INFO:     10.20.41.203:0 - "GET /getMonths_images HTTP/1.1" 500 Internal Server Error
ERROR:    Exception in ASGI application
Traceback (most recent call last):
  File "/usr/local/lib/python3.7/dist-packages/uvicorn/protocols/http/httptools_impl.py", line 375, in run_asgi
    result = await app(self.scope, self.receive, self.send)
  File "/usr/local/lib/python3.7/dist-packages/uvicorn/middleware/proxy_headers.py", line 75, in __call__
    return await self.app(scope, receive, send)
  File "/usr/local/lib/python3.7/dist-packages/fastapi/applications.py", line 208, in __call__
    await super().__call__(scope, receive, send)
  File "/usr/local/lib/python3.7/dist-packages/starlette/applications.py", line 112, in __call__
    await self.middleware_stack(scope, receive, send)
  File "/usr/local/lib/python3.7/dist-packages/starlette/middleware/errors.py", line 181, in __call__
    raise exc
  File "/usr/local/lib/python3.7/dist-packages/starlette/middleware/errors.py", line 159, in __call__
    await self.app(scope, receive, _send)
  File "/usr/local/lib/python3.7/dist-packages/starlette/exceptions.py", line 82, in __call__
    raise exc
  File "/usr/local/lib/python3.7/dist-packages/starlette/exceptions.py", line 71, in __call__
    await self.app(scope, receive, sender)
  File "/usr/local/lib/python3.7/dist-packages/starlette/routing.py", line 656, in __call__
    await route.handle(scope, receive, send)
  File "/usr/local/lib/python3.7/dist-packages/starlette/routing.py", line 259, in handle
    await self.app(scope, receive, send)
  File "/usr/local/lib/python3.7/dist-packages/starlette/routing.py", line 61, in app
    response = await func(request)
  File "/usr/local/lib/python3.7/dist-packages/fastapi/routing.py", line 227, in app
    dependant=dependant, values=values, is_coroutine=is_coroutine
  File "/usr/local/lib/python3.7/dist-packages/fastapi/routing.py", line 161, in run_endpoint_function
    return await run_in_threadpool(dependant.call, **values)
  File "/usr/local/lib/python3.7/dist-packages/starlette/concurrency.py", line 39, in run_in_threadpool
    return await anyio.to_thread.run_sync(func, *args)
  File "/usr/local/lib/python3.7/dist-packages/anyio/to_thread.py", line 29, in run_sync
    limiter=limiter)
  File "/usr/local/lib/python3.7/dist-packages/anyio/_backends/_asyncio.py", line 818, in run_sync_in_worker_thread
    return await future
  File "/usr/local/lib/python3.7/dist-packages/anyio/_backends/_asyncio.py", line 754, in run
    result = context.run(func, *args)
  File "./main.py", line 54, in read_root
    ls = os.listdir("../images")
FileNotFoundError: [Errno 2] No such file or directory: '../images'
ERROR:uvicorn.error:Exception in ASGI application
Traceback (most recent call last):
  File "/usr/local/lib/python3.7/dist-packages/uvicorn/protocols/http/httptools_impl.py", line 375, in run_asgi
    result = await app(self.scope, self.receive, self.send)
  File "/usr/local/lib/python3.7/dist-packages/uvicorn/middleware/proxy_headers.py", line 75, in __call__
    return await self.app(scope, receive, send)
  File "/usr/local/lib/python3.7/dist-packages/fastapi/applications.py", line 208, in __call__
    await super().__call__(scope, receive, send)
  File "/usr/local/lib/python3.7/dist-packages/starlette/applications.py", line 112, in __call__
    await self.middleware_stack(scope, receive, send)
  File "/usr/local/lib/python3.7/dist-packages/starlette/middleware/errors.py", line 181, in __call__
    raise exc
  File "/usr/local/lib/python3.7/dist-packages/starlette/middleware/errors.py", line 159, in __call__
    await self.app(scope, receive, _send)
  File "/usr/local/lib/python3.7/dist-packages/starlette/exceptions.py", line 82, in __call__
    raise exc
  File "/usr/local/lib/python3.7/dist-packages/starlette/exceptions.py", line 71, in __call__
    await self.app(scope, receive, sender)
  File "/usr/local/lib/python3.7/dist-packages/starlette/routing.py", line 656, in __call__
    await route.handle(scope, receive, send)
  File "/usr/local/lib/python3.7/dist-packages/starlette/routing.py", line 259, in handle
    await self.app(scope, receive, send)
  File "/usr/local/lib/python3.7/dist-packages/starlette/routing.py", line 61, in app
    response = await func(request)
  File "/usr/local/lib/python3.7/dist-packages/fastapi/routing.py", line 227, in app
    dependant=dependant, values=values, is_coroutine=is_coroutine
  File "/usr/local/lib/python3.7/dist-packages/fastapi/routing.py", line 161, in run_endpoint_function
    return await run_in_threadpool(dependant.call, **values)
  File "/usr/local/lib/python3.7/dist-packages/starlette/concurrency.py", line 39, in run_in_threadpool
    return await anyio.to_thread.run_sync(func, *args)
  File "/usr/local/lib/python3.7/dist-packages/anyio/to_thread.py", line 29, in run_sync
    limiter=limiter)
  File "/usr/local/lib/python3.7/dist-packages/anyio/_backends/_asyncio.py", line 818, in run_sync_in_worker_thread
    return await future
  File "/usr/local/lib/python3.7/dist-packages/anyio/_backends/_asyncio.py", line 754, in run
    result = context.run(func, *args)
  File "./main.py", line 54, in read_root
    ls = os.listdir("../images")
FileNotFoundError: [Errno 2] No such file or directory: '../images'
INFO:     10.20.41.203:0 - "GET /getMonths_images HTTP/1.1" 500 Internal Server Error
ERROR:    Exception in ASGI application
Traceback (most recent call last):
  File "/usr/local/lib/python3.7/dist-packages/uvicorn/protocols/http/httptools_impl.py", line 375, in run_asgi
    result = await app(self.scope, self.receive, self.send)
  File "/usr/local/lib/python3.7/dist-packages/uvicorn/middleware/proxy_headers.py", line 75, in __call__
    return await self.app(scope, receive, send)
  File "/usr/local/lib/python3.7/dist-packages/fastapi/applications.py", line 208, in __call__
    await super().__call__(scope, receive, send)
  File "/usr/local/lib/python3.7/dist-packages/starlette/applications.py", line 112, in __call__
    await self.middleware_stack(scope, receive, send)
  File "/usr/local/lib/python3.7/dist-packages/starlette/middleware/errors.py", line 181, in __call__
    raise exc
  File "/usr/local/lib/python3.7/dist-packages/starlette/middleware/errors.py", line 159, in __call__
    await self.app(scope, receive, _send)
  File "/usr/local/lib/python3.7/dist-packages/starlette/exceptions.py", line 82, in __call__
    raise exc
  File "/usr/local/lib/python3.7/dist-packages/starlette/exceptions.py", line 71, in __call__
    await self.app(scope, receive, sender)
  File "/usr/local/lib/python3.7/dist-packages/starlette/routing.py", line 656, in __call__
    await route.handle(scope, receive, send)
  File "/usr/local/lib/python3.7/dist-packages/starlette/routing.py", line 259, in handle
    await self.app(scope, receive, send)
  File "/usr/local/lib/python3.7/dist-packages/starlette/routing.py", line 61, in app
    response = await func(request)
  File "/usr/local/lib/python3.7/dist-packages/fastapi/routing.py", line 227, in app
    dependant=dependant, values=values, is_coroutine=is_coroutine
  File "/usr/local/lib/python3.7/dist-packages/fastapi/routing.py", line 161, in run_endpoint_function
    return await run_in_threadpool(dependant.call, **values)
  File "/usr/local/lib/python3.7/dist-packages/starlette/concurrency.py", line 39, in run_in_threadpool
    return await anyio.to_thread.run_sync(func, *args)
  File "/usr/local/lib/python3.7/dist-packages/anyio/to_thread.py", line 29, in run_sync
    limiter=limiter)
  File "/usr/local/lib/python3.7/dist-packages/anyio/_backends/_asyncio.py", line 818, in run_sync_in_worker_thread
    return await future
  File "/usr/local/lib/python3.7/dist-packages/anyio/_backends/_asyncio.py", line 754, in run
    result = context.run(func, *args)
  File "./main.py", line 54, in read_root
    ls = os.listdir("../images")
FileNotFoundError: [Errno 2] No such file or directory: '../images'
ERROR:uvicorn.error:Exception in ASGI application
Traceback (most recent call last):
  File "/usr/local/lib/python3.7/dist-packages/uvicorn/protocols/http/httptools_impl.py", line 375, in run_asgi
    result = await app(self.scope, self.receive, self.send)
  File "/usr/local/lib/python3.7/dist-packages/uvicorn/middleware/proxy_headers.py", line 75, in __call__
    return await self.app(scope, receive, send)
  File "/usr/local/lib/python3.7/dist-packages/fastapi/applications.py", line 208, in __call__
    await super().__call__(scope, receive, send)
  File "/usr/local/lib/python3.7/dist-packages/starlette/applications.py", line 112, in __call__
    await self.middleware_stack(scope, receive, send)
  File "/usr/local/lib/python3.7/dist-packages/starlette/middleware/errors.py", line 181, in __call__
    raise exc
  File "/usr/local/lib/python3.7/dist-packages/starlette/middleware/errors.py", line 159, in __call__
    await self.app(scope, receive, _send)
  File "/usr/local/lib/python3.7/dist-packages/starlette/exceptions.py", line 82, in __call__
    raise exc
  File "/usr/local/lib/python3.7/dist-packages/starlette/exceptions.py", line 71, in __call__
    await self.app(scope, receive, sender)
  File "/usr/local/lib/python3.7/dist-packages/starlette/routing.py", line 656, in __call__
    await route.handle(scope, receive, send)
  File "/usr/local/lib/python3.7/dist-packages/starlette/routing.py", line 259, in handle
    await self.app(scope, receive, send)
  File "/usr/local/lib/python3.7/dist-packages/starlette/routing.py", line 61, in app
    response = await func(request)
  File "/usr/local/lib/python3.7/dist-packages/fastapi/routing.py", line 227, in app
    dependant=dependant, values=values, is_coroutine=is_coroutine
  File "/usr/local/lib/python3.7/dist-packages/fastapi/routing.py", line 161, in run_endpoint_function
    return await run_in_threadpool(dependant.call, **values)
  File "/usr/local/lib/python3.7/dist-packages/starlette/concurrency.py", line 39, in run_in_threadpool
    return await anyio.to_thread.run_sync(func, *args)
  File "/usr/local/lib/python3.7/dist-packages/anyio/to_thread.py", line 29, in run_sync
    limiter=limiter)
  File "/usr/local/lib/python3.7/dist-packages/anyio/_backends/_asyncio.py", line 818, in run_sync_in_worker_thread
    return await future
  File "/usr/local/lib/python3.7/dist-packages/anyio/_backends/_asyncio.py", line 754, in run
    result = context.run(func, *args)
  File "./main.py", line 54, in read_root
    ls = os.listdir("../images")
FileNotFoundError: [Errno 2] No such file or directory: '../images'
WARNING:  WatchGodReload detected file change in '['/root/IT3530-Project/server/main.py']'. Reloading...
INFO:     Shutting down
INFO:uvicorn.error:Shutting down
INFO:     Waiting for application shutdown.
INFO:uvicorn.error:Waiting for application shutdown.
INFO:     Application shutdown complete.
INFO:uvicorn.error:Application shutdown complete.
INFO:     Finished server process [2412]
INFO:uvicorn.error:Finished server process [2412]
./main.py:9: RuntimeWarning: This channel is already in use, continuing anyway.  Use GPIO.setwarnings(False) to disable warnings.
  GPIO.setup(20, GPIO.OUT)
INFO:     Started server process [2427]
INFO:uvicorn.error:Started server process [2427]
INFO:     Waiting for application startup.
INFO:uvicorn.error:Waiting for application startup.
INFO:     Application startup complete.
INFO:uvicorn.error:Application startup complete.
INFO:     10.20.41.203:0 - "GET /getMonths_images HTTP/1.1" 200 OK
INFO:     Will watch for changes in these directories: ['/root/IT3530-Project/server']
INFO:     Uvicorn running on http://0.0.0.0:80 (Press CTRL+C to quit)
INFO:     Started reloader process [785] using watchgod
INFO:     Started server process [788]
INFO:uvicorn.error:Started server process [788]
INFO:     Waiting for application startup.
INFO:uvicorn.error:Waiting for application startup.
INFO:     Application startup complete.
INFO:uvicorn.error:Application startup complete.
INFO:     10.20.40.10:0 - "GET /getImage?monthAndDayAndHourAndMinAndImageID=/11/26/23/9/54.jpg HTTP/1.1" 500 Internal Server Error
ERROR:    Exception in ASGI application
Traceback (most recent call last):
  File "/usr/local/lib/python3.7/dist-packages/uvicorn/protocols/http/httptools_impl.py", line 375, in run_asgi
    result = await app(self.scope, self.receive, self.send)
  File "/usr/local/lib/python3.7/dist-packages/uvicorn/middleware/proxy_headers.py", line 75, in __call__
    return await self.app(scope, receive, send)
  File "/usr/local/lib/python3.7/dist-packages/fastapi/applications.py", line 208, in __call__
    await super().__call__(scope, receive, send)
  File "/usr/local/lib/python3.7/dist-packages/starlette/applications.py", line 112, in __call__
    await self.middleware_stack(scope, receive, send)
  File "/usr/local/lib/python3.7/dist-packages/starlette/middleware/errors.py", line 181, in __call__
    raise exc
  File "/usr/local/lib/python3.7/dist-packages/starlette/middleware/errors.py", line 159, in __call__
    await self.app(scope, receive, _send)
  File "/usr/local/lib/python3.7/dist-packages/starlette/exceptions.py", line 82, in __call__
    raise exc
  File "/usr/local/lib/python3.7/dist-packages/starlette/exceptions.py", line 71, in __call__
    await self.app(scope, receive, sender)
  File "/usr/local/lib/python3.7/dist-packages/starlette/routing.py", line 656, in __call__
    await route.handle(scope, receive, send)
  File "/usr/local/lib/python3.7/dist-packages/starlette/routing.py", line 259, in handle
    await self.app(scope, receive, send)
  File "/usr/local/lib/python3.7/dist-packages/starlette/routing.py", line 61, in app
    response = await func(request)
  File "/usr/local/lib/python3.7/dist-packages/fastapi/routing.py", line 227, in app
    dependant=dependant, values=values, is_coroutine=is_coroutine
  File "/usr/local/lib/python3.7/dist-packages/fastapi/routing.py", line 161, in run_endpoint_function
    return await run_in_threadpool(dependant.call, **values)
  File "/usr/local/lib/python3.7/dist-packages/starlette/concurrency.py", line 39, in run_in_threadpool
    return await anyio.to_thread.run_sync(func, *args)
  File "/usr/local/lib/python3.7/dist-packages/anyio/to_thread.py", line 29, in run_sync
    limiter=limiter)
  File "/usr/local/lib/python3.7/dist-packages/anyio/_backends/_asyncio.py", line 818, in run_sync_in_worker_thread
    return await future
  File "/usr/local/lib/python3.7/dist-packages/anyio/_backends/_asyncio.py", line 754, in run
    result = context.run(func, *args)
  File "./main.py", line 94, in read_root
    ls = os.listdir("./images/"+monthAndDayAndHourAndMinAndImageID)
NotADirectoryError: [Errno 20] Not a directory: './images//11/26/23/9/54.jpg'
ERROR:uvicorn.error:Exception in ASGI application
Traceback (most recent call last):
  File "/usr/local/lib/python3.7/dist-packages/uvicorn/protocols/http/httptools_impl.py", line 375, in run_asgi
    result = await app(self.scope, self.receive, self.send)
  File "/usr/local/lib/python3.7/dist-packages/uvicorn/middleware/proxy_headers.py", line 75, in __call__
    return await self.app(scope, receive, send)
  File "/usr/local/lib/python3.7/dist-packages/fastapi/applications.py", line 208, in __call__
    await super().__call__(scope, receive, send)
  File "/usr/local/lib/python3.7/dist-packages/starlette/applications.py", line 112, in __call__
    await self.middleware_stack(scope, receive, send)
  File "/usr/local/lib/python3.7/dist-packages/starlette/middleware/errors.py", line 181, in __call__
    raise exc
  File "/usr/local/lib/python3.7/dist-packages/starlette/middleware/errors.py", line 159, in __call__
    await self.app(scope, receive, _send)
  File "/usr/local/lib/python3.7/dist-packages/starlette/exceptions.py", line 82, in __call__
    raise exc
  File "/usr/local/lib/python3.7/dist-packages/starlette/exceptions.py", line 71, in __call__
    await self.app(scope, receive, sender)
  File "/usr/local/lib/python3.7/dist-packages/starlette/routing.py", line 656, in __call__
    await route.handle(scope, receive, send)
  File "/usr/local/lib/python3.7/dist-packages/starlette/routing.py", line 259, in handle
    await self.app(scope, receive, send)
  File "/usr/local/lib/python3.7/dist-packages/starlette/routing.py", line 61, in app
    response = await func(request)
  File "/usr/local/lib/python3.7/dist-packages/fastapi/routing.py", line 227, in app
    dependant=dependant, values=values, is_coroutine=is_coroutine
  File "/usr/local/lib/python3.7/dist-packages/fastapi/routing.py", line 161, in run_endpoint_function
    return await run_in_threadpool(dependant.call, **values)
  File "/usr/local/lib/python3.7/dist-packages/starlette/concurrency.py", line 39, in run_in_threadpool
    return await anyio.to_thread.run_sync(func, *args)
  File "/usr/local/lib/python3.7/dist-packages/anyio/to_thread.py", line 29, in run_sync
    limiter=limiter)
  File "/usr/local/lib/python3.7/dist-packages/anyio/_backends/_asyncio.py", line 818, in run_sync_in_worker_thread
    return await future
  File "/usr/local/lib/python3.7/dist-packages/anyio/_backends/_asyncio.py", line 754, in run
    result = context.run(func, *args)
  File "./main.py", line 94, in read_root
    ls = os.listdir("./images/"+monthAndDayAndHourAndMinAndImageID)
NotADirectoryError: [Errno 20] Not a directory: './images//11/26/23/9/54.jpg'
INFO:     10.20.40.10:0 - "GET /getImage?monthAndDayAndHourAndMinAndImageID=/11/26/23/9/54.jpg HTTP/1.1" 500 Internal Server Error
ERROR:    Exception in ASGI application
Traceback (most recent call last):
  File "/usr/local/lib/python3.7/dist-packages/uvicorn/protocols/http/httptools_impl.py", line 375, in run_asgi
    result = await app(self.scope, self.receive, self.send)
  File "/usr/local/lib/python3.7/dist-packages/uvicorn/middleware/proxy_headers.py", line 75, in __call__
    return await self.app(scope, receive, send)
  File "/usr/local/lib/python3.7/dist-packages/fastapi/applications.py", line 208, in __call__
    await super().__call__(scope, receive, send)
  File "/usr/local/lib/python3.7/dist-packages/starlette/applications.py", line 112, in __call__
    await self.middleware_stack(scope, receive, send)
  File "/usr/local/lib/python3.7/dist-packages/starlette/middleware/errors.py", line 181, in __call__
    raise exc
  File "/usr/local/lib/python3.7/dist-packages/starlette/middleware/errors.py", line 159, in __call__
    await self.app(scope, receive, _send)
  File "/usr/local/lib/python3.7/dist-packages/starlette/exceptions.py", line 82, in __call__
    raise exc
  File "/usr/local/lib/python3.7/dist-packages/starlette/exceptions.py", line 71, in __call__
    await self.app(scope, receive, sender)
  File "/usr/local/lib/python3.7/dist-packages/starlette/routing.py", line 656, in __call__
    await route.handle(scope, receive, send)
  File "/usr/local/lib/python3.7/dist-packages/starlette/routing.py", line 259, in handle
    await self.app(scope, receive, send)
  File "/usr/local/lib/python3.7/dist-packages/starlette/routing.py", line 61, in app
    response = await func(request)
  File "/usr/local/lib/python3.7/dist-packages/fastapi/routing.py", line 227, in app
    dependant=dependant, values=values, is_coroutine=is_coroutine
  File "/usr/local/lib/python3.7/dist-packages/fastapi/routing.py", line 161, in run_endpoint_function
    return await run_in_threadpool(dependant.call, **values)
  File "/usr/local/lib/python3.7/dist-packages/starlette/concurrency.py", line 39, in run_in_threadpool
    return await anyio.to_thread.run_sync(func, *args)
  File "/usr/local/lib/python3.7/dist-packages/anyio/to_thread.py", line 29, in run_sync
    limiter=limiter)
  File "/usr/local/lib/python3.7/dist-packages/anyio/_backends/_asyncio.py", line 818, in run_sync_in_worker_thread
    return await future
  File "/usr/local/lib/python3.7/dist-packages/anyio/_backends/_asyncio.py", line 754, in run
    result = context.run(func, *args)
  File "./main.py", line 94, in read_root
    ls = os.listdir("./images/"+monthAndDayAndHourAndMinAndImageID)
NotADirectoryError: [Errno 20] Not a directory: './images//11/26/23/9/54.jpg'
ERROR:uvicorn.error:Exception in ASGI application
Traceback (most recent call last):
  File "/usr/local/lib/python3.7/dist-packages/uvicorn/protocols/http/httptools_impl.py", line 375, in run_asgi
    result = await app(self.scope, self.receive, self.send)
  File "/usr/local/lib/python3.7/dist-packages/uvicorn/middleware/proxy_headers.py", line 75, in __call__
    return await self.app(scope, receive, send)
  File "/usr/local/lib/python3.7/dist-packages/fastapi/applications.py", line 208, in __call__
    await super().__call__(scope, receive, send)
  File "/usr/local/lib/python3.7/dist-packages/starlette/applications.py", line 112, in __call__
    await self.middleware_stack(scope, receive, send)
  File "/usr/local/lib/python3.7/dist-packages/starlette/middleware/errors.py", line 181, in __call__
    raise exc
  File "/usr/local/lib/python3.7/dist-packages/starlette/middleware/errors.py", line 159, in __call__
    await self.app(scope, receive, _send)
  File "/usr/local/lib/python3.7/dist-packages/starlette/exceptions.py", line 82, in __call__
    raise exc
  File "/usr/local/lib/python3.7/dist-packages/starlette/exceptions.py", line 71, in __call__
    await self.app(scope, receive, sender)
  File "/usr/local/lib/python3.7/dist-packages/starlette/routing.py", line 656, in __call__
    await route.handle(scope, receive, send)
  File "/usr/local/lib/python3.7/dist-packages/starlette/routing.py", line 259, in handle
    await self.app(scope, receive, send)
  File "/usr/local/lib/python3.7/dist-packages/starlette/routing.py", line 61, in app
    response = await func(request)
  File "/usr/local/lib/python3.7/dist-packages/fastapi/routing.py", line 227, in app
    dependant=dependant, values=values, is_coroutine=is_coroutine
  File "/usr/local/lib/python3.7/dist-packages/fastapi/routing.py", line 161, in run_endpoint_function
    return await run_in_threadpool(dependant.call, **values)
  File "/usr/local/lib/python3.7/dist-packages/starlette/concurrency.py", line 39, in run_in_threadpool
    return await anyio.to_thread.run_sync(func, *args)
  File "/usr/local/lib/python3.7/dist-packages/anyio/to_thread.py", line 29, in run_sync
    limiter=limiter)
  File "/usr/local/lib/python3.7/dist-packages/anyio/_backends/_asyncio.py", line 818, in run_sync_in_worker_thread
    return await future
  File "/usr/local/lib/python3.7/dist-packages/anyio/_backends/_asyncio.py", line 754, in run
    result = context.run(func, *args)
  File "./main.py", line 94, in read_root
    ls = os.listdir("./images/"+monthAndDayAndHourAndMinAndImageID)
NotADirectoryError: [Errno 20] Not a directory: './images//11/26/23/9/54.jpg'
INFO:     10.20.41.203:0 - "GET /getImage?monthAndDayAndHourAndMinAndImageID=/11/26/23/9/54.jpg HTTP/1.1" 500 Internal Server Error
ERROR:    Exception in ASGI application
Traceback (most recent call last):
  File "/usr/local/lib/python3.7/dist-packages/uvicorn/protocols/http/httptools_impl.py", line 375, in run_asgi
    result = await app(self.scope, self.receive, self.send)
  File "/usr/local/lib/python3.7/dist-packages/uvicorn/middleware/proxy_headers.py", line 75, in __call__
    return await self.app(scope, receive, send)
  File "/usr/local/lib/python3.7/dist-packages/fastapi/applications.py", line 208, in __call__
    await super().__call__(scope, receive, send)
  File "/usr/local/lib/python3.7/dist-packages/starlette/applications.py", line 112, in __call__
    await self.middleware_stack(scope, receive, send)
  File "/usr/local/lib/python3.7/dist-packages/starlette/middleware/errors.py", line 181, in __call__
    raise exc
  File "/usr/local/lib/python3.7/dist-packages/starlette/middleware/errors.py", line 159, in __call__
    await self.app(scope, receive, _send)
  File "/usr/local/lib/python3.7/dist-packages/starlette/exceptions.py", line 82, in __call__
    raise exc
  File "/usr/local/lib/python3.7/dist-packages/starlette/exceptions.py", line 71, in __call__
    await self.app(scope, receive, sender)
  File "/usr/local/lib/python3.7/dist-packages/starlette/routing.py", line 656, in __call__
    await route.handle(scope, receive, send)
  File "/usr/local/lib/python3.7/dist-packages/starlette/routing.py", line 259, in handle
    await self.app(scope, receive, send)
  File "/usr/local/lib/python3.7/dist-packages/starlette/routing.py", line 61, in app
    response = await func(request)
  File "/usr/local/lib/python3.7/dist-packages/fastapi/routing.py", line 227, in app
    dependant=dependant, values=values, is_coroutine=is_coroutine
  File "/usr/local/lib/python3.7/dist-packages/fastapi/routing.py", line 161, in run_endpoint_function
    return await run_in_threadpool(dependant.call, **values)
  File "/usr/local/lib/python3.7/dist-packages/starlette/concurrency.py", line 39, in run_in_threadpool
    return await anyio.to_thread.run_sync(func, *args)
  File "/usr/local/lib/python3.7/dist-packages/anyio/to_thread.py", line 29, in run_sync
    limiter=limiter)
  File "/usr/local/lib/python3.7/dist-packages/anyio/_backends/_asyncio.py", line 818, in run_sync_in_worker_thread
    return await future
  File "/usr/local/lib/python3.7/dist-packages/anyio/_backends/_asyncio.py", line 754, in run
    result = context.run(func, *args)
  File "./main.py", line 94, in read_root
    ls = os.listdir("./images/"+monthAndDayAndHourAndMinAndImageID)
NotADirectoryError: [Errno 20] Not a directory: './images//11/26/23/9/54.jpg'
ERROR:uvicorn.error:Exception in ASGI application
Traceback (most recent call last):
  File "/usr/local/lib/python3.7/dist-packages/uvicorn/protocols/http/httptools_impl.py", line 375, in run_asgi
    result = await app(self.scope, self.receive, self.send)
  File "/usr/local/lib/python3.7/dist-packages/uvicorn/middleware/proxy_headers.py", line 75, in __call__
    return await self.app(scope, receive, send)
  File "/usr/local/lib/python3.7/dist-packages/fastapi/applications.py", line 208, in __call__
    await super().__call__(scope, receive, send)
  File "/usr/local/lib/python3.7/dist-packages/starlette/applications.py", line 112, in __call__
    await self.middleware_stack(scope, receive, send)
  File "/usr/local/lib/python3.7/dist-packages/starlette/middleware/errors.py", line 181, in __call__
    raise exc
  File "/usr/local/lib/python3.7/dist-packages/starlette/middleware/errors.py", line 159, in __call__
    await self.app(scope, receive, _send)
  File "/usr/local/lib/python3.7/dist-packages/starlette/exceptions.py", line 82, in __call__
    raise exc
  File "/usr/local/lib/python3.7/dist-packages/starlette/exceptions.py", line 71, in __call__
    await self.app(scope, receive, sender)
  File "/usr/local/lib/python3.7/dist-packages/starlette/routing.py", line 656, in __call__
    await route.handle(scope, receive, send)
  File "/usr/local/lib/python3.7/dist-packages/starlette/routing.py", line 259, in handle
    await self.app(scope, receive, send)
  File "/usr/local/lib/python3.7/dist-packages/starlette/routing.py", line 61, in app
    response = await func(request)
  File "/usr/local/lib/python3.7/dist-packages/fastapi/routing.py", line 227, in app
    dependant=dependant, values=values, is_coroutine=is_coroutine
  File "/usr/local/lib/python3.7/dist-packages/fastapi/routing.py", line 161, in run_endpoint_function
    return await run_in_threadpool(dependant.call, **values)
  File "/usr/local/lib/python3.7/dist-packages/starlette/concurrency.py", line 39, in run_in_threadpool
    return await anyio.to_thread.run_sync(func, *args)
  File "/usr/local/lib/python3.7/dist-packages/anyio/to_thread.py", line 29, in run_sync
    limiter=limiter)
  File "/usr/local/lib/python3.7/dist-packages/anyio/_backends/_asyncio.py", line 818, in run_sync_in_worker_thread
    return await future
  File "/usr/local/lib/python3.7/dist-packages/anyio/_backends/_asyncio.py", line 754, in run
    result = context.run(func, *args)
  File "./main.py", line 94, in read_root
    ls = os.listdir("./images/"+monthAndDayAndHourAndMinAndImageID)
NotADirectoryError: [Errno 20] Not a directory: './images//11/26/23/9/54.jpg'
INFO:     10.20.41.203:0 - "GET /getImage?monthAndDayAndHourAndMinAndImageID=11/26/23/9/54.jpg HTTP/1.1" 500 Internal Server Error
ERROR:    Exception in ASGI application
Traceback (most recent call last):
  File "/usr/local/lib/python3.7/dist-packages/uvicorn/protocols/http/httptools_impl.py", line 375, in run_asgi
    result = await app(self.scope, self.receive, self.send)
  File "/usr/local/lib/python3.7/dist-packages/uvicorn/middleware/proxy_headers.py", line 75, in __call__
    return await self.app(scope, receive, send)
  File "/usr/local/lib/python3.7/dist-packages/fastapi/applications.py", line 208, in __call__
    await super().__call__(scope, receive, send)
  File "/usr/local/lib/python3.7/dist-packages/starlette/applications.py", line 112, in __call__
    await self.middleware_stack(scope, receive, send)
  File "/usr/local/lib/python3.7/dist-packages/starlette/middleware/errors.py", line 181, in __call__
    raise exc
  File "/usr/local/lib/python3.7/dist-packages/starlette/middleware/errors.py", line 159, in __call__
    await self.app(scope, receive, _send)
  File "/usr/local/lib/python3.7/dist-packages/starlette/exceptions.py", line 82, in __call__
    raise exc
  File "/usr/local/lib/python3.7/dist-packages/starlette/exceptions.py", line 71, in __call__
    await self.app(scope, receive, sender)
  File "/usr/local/lib/python3.7/dist-packages/starlette/routing.py", line 656, in __call__
    await route.handle(scope, receive, send)
  File "/usr/local/lib/python3.7/dist-packages/starlette/routing.py", line 259, in handle
    await self.app(scope, receive, send)
  File "/usr/local/lib/python3.7/dist-packages/starlette/routing.py", line 61, in app
    response = await func(request)
  File "/usr/local/lib/python3.7/dist-packages/fastapi/routing.py", line 227, in app
    dependant=dependant, values=values, is_coroutine=is_coroutine
  File "/usr/local/lib/python3.7/dist-packages/fastapi/routing.py", line 161, in run_endpoint_function
    return await run_in_threadpool(dependant.call, **values)
  File "/usr/local/lib/python3.7/dist-packages/starlette/concurrency.py", line 39, in run_in_threadpool
    return await anyio.to_thread.run_sync(func, *args)
  File "/usr/local/lib/python3.7/dist-packages/anyio/to_thread.py", line 29, in run_sync
    limiter=limiter)
  File "/usr/local/lib/python3.7/dist-packages/anyio/_backends/_asyncio.py", line 818, in run_sync_in_worker_thread
    return await future
  File "/usr/local/lib/python3.7/dist-packages/anyio/_backends/_asyncio.py", line 754, in run
    result = context.run(func, *args)
  File "./main.py", line 94, in read_root
    ls = os.listdir("./images/"+monthAndDayAndHourAndMinAndImageID)
NotADirectoryError: [Errno 20] Not a directory: './images/11/26/23/9/54.jpg'
ERROR:uvicorn.error:Exception in ASGI application
Traceback (most recent call last):
  File "/usr/local/lib/python3.7/dist-packages/uvicorn/protocols/http/httptools_impl.py", line 375, in run_asgi
    result = await app(self.scope, self.receive, self.send)
  File "/usr/local/lib/python3.7/dist-packages/uvicorn/middleware/proxy_headers.py", line 75, in __call__
    return await self.app(scope, receive, send)
  File "/usr/local/lib/python3.7/dist-packages/fastapi/applications.py", line 208, in __call__
    await super().__call__(scope, receive, send)
  File "/usr/local/lib/python3.7/dist-packages/starlette/applications.py", line 112, in __call__
    await self.middleware_stack(scope, receive, send)
  File "/usr/local/lib/python3.7/dist-packages/starlette/middleware/errors.py", line 181, in __call__
    raise exc
  File "/usr/local/lib/python3.7/dist-packages/starlette/middleware/errors.py", line 159, in __call__
    await self.app(scope, receive, _send)
  File "/usr/local/lib/python3.7/dist-packages/starlette/exceptions.py", line 82, in __call__
    raise exc
  File "/usr/local/lib/python3.7/dist-packages/starlette/exceptions.py", line 71, in __call__
    await self.app(scope, receive, sender)
  File "/usr/local/lib/python3.7/dist-packages/starlette/routing.py", line 656, in __call__
    await route.handle(scope, receive, send)
  File "/usr/local/lib/python3.7/dist-packages/starlette/routing.py", line 259, in handle
    await self.app(scope, receive, send)
  File "/usr/local/lib/python3.7/dist-packages/starlette/routing.py", line 61, in app
    response = await func(request)
  File "/usr/local/lib/python3.7/dist-packages/fastapi/routing.py", line 227, in app
    dependant=dependant, values=values, is_coroutine=is_coroutine
  File "/usr/local/lib/python3.7/dist-packages/fastapi/routing.py", line 161, in run_endpoint_function
    return await run_in_threadpool(dependant.call, **values)
  File "/usr/local/lib/python3.7/dist-packages/starlette/concurrency.py", line 39, in run_in_threadpool
    return await anyio.to_thread.run_sync(func, *args)
  File "/usr/local/lib/python3.7/dist-packages/anyio/to_thread.py", line 29, in run_sync
    limiter=limiter)
  File "/usr/local/lib/python3.7/dist-packages/anyio/_backends/_asyncio.py", line 818, in run_sync_in_worker_thread
    return await future
  File "/usr/local/lib/python3.7/dist-packages/anyio/_backends/_asyncio.py", line 754, in run
    result = context.run(func, *args)
  File "./main.py", line 94, in read_root
    ls = os.listdir("./images/"+monthAndDayAndHourAndMinAndImageID)
NotADirectoryError: [Errno 20] Not a directory: './images/11/26/23/9/54.jpg'
WARNING:  WatchGodReload detected file change in '['/root/IT3530-Project/server/main.py']'. Reloading...
INFO:     Shutting down
INFO:uvicorn.error:Shutting down
INFO:     Waiting for application shutdown.
INFO:uvicorn.error:Waiting for application shutdown.
INFO:     Application shutdown complete.
INFO:uvicorn.error:Application shutdown complete.
INFO:     Finished server process [788]
INFO:uvicorn.error:Finished server process [788]
ERROR:    Error loading ASGI app. Could not import module "main".
WARNING:  WatchGodReload detected file change in '['/root/IT3530-Project/server/main.py']'. Reloading...
./main.py:9: RuntimeWarning: This channel is already in use, continuing anyway.  Use GPIO.setwarnings(False) to disable warnings.
  GPIO.setup(20, GPIO.OUT)
INFO:     Started server process [839]
INFO:uvicorn.error:Started server process [839]
INFO:     Waiting for application startup.
INFO:uvicorn.error:Waiting for application startup.
INFO:     Application startup complete.
INFO:uvicorn.error:Application startup complete.
INFO:     10.20.41.203:0 - "GET /getImage?monthAndDayAndHourAndMinAndImageID=11/26/23/9/54.jpg HTTP/1.1" 200 OK
INFO:     10.20.41.203:0 - "GET /getImage?monthAndDayAndHourAndMinAndImageID=11/26/23/9/55.jpg HTTP/1.1" 500 Internal Server Error
ERROR:    Exception in ASGI application
Traceback (most recent call last):
  File "/usr/local/lib/python3.7/dist-packages/starlette/responses.py", line 282, in __call__
    stat_result = await anyio.to_thread.run_sync(os.stat, self.path)
  File "/usr/local/lib/python3.7/dist-packages/anyio/to_thread.py", line 29, in run_sync
    limiter=limiter)
  File "/usr/local/lib/python3.7/dist-packages/anyio/_backends/_asyncio.py", line 818, in run_sync_in_worker_thread
    return await future
  File "/usr/local/lib/python3.7/dist-packages/anyio/_backends/_asyncio.py", line 754, in run
    result = context.run(func, *args)
FileNotFoundError: [Errno 2] No such file or directory: './images/11/26/23/9/55.jpg'

During handling of the above exception, another exception occurred:

Traceback (most recent call last):
  File "/usr/local/lib/python3.7/dist-packages/uvicorn/protocols/http/httptools_impl.py", line 375, in run_asgi
    result = await app(self.scope, self.receive, self.send)
  File "/usr/local/lib/python3.7/dist-packages/uvicorn/middleware/proxy_headers.py", line 75, in __call__
    return await self.app(scope, receive, send)
  File "/usr/local/lib/python3.7/dist-packages/fastapi/applications.py", line 208, in __call__
    await super().__call__(scope, receive, send)
  File "/usr/local/lib/python3.7/dist-packages/starlette/applications.py", line 112, in __call__
    await self.middleware_stack(scope, receive, send)
  File "/usr/local/lib/python3.7/dist-packages/starlette/middleware/errors.py", line 181, in __call__
    raise exc
  File "/usr/local/lib/python3.7/dist-packages/starlette/middleware/errors.py", line 159, in __call__
    await self.app(scope, receive, _send)
  File "/usr/local/lib/python3.7/dist-packages/starlette/exceptions.py", line 82, in __call__
    raise exc
  File "/usr/local/lib/python3.7/dist-packages/starlette/exceptions.py", line 71, in __call__
    await self.app(scope, receive, sender)
  File "/usr/local/lib/python3.7/dist-packages/starlette/routing.py", line 656, in __call__
    await route.handle(scope, receive, send)
  File "/usr/local/lib/python3.7/dist-packages/starlette/routing.py", line 259, in handle
    await self.app(scope, receive, send)
  File "/usr/local/lib/python3.7/dist-packages/starlette/routing.py", line 64, in app
    await response(scope, receive, send)
  File "/usr/local/lib/python3.7/dist-packages/starlette/responses.py", line 285, in __call__
    raise RuntimeError(f"File at path {self.path} does not exist.")
RuntimeError: File at path ./images/11/26/23/9/55.jpg does not exist.
ERROR:uvicorn.error:Exception in ASGI application
Traceback (most recent call last):
  File "/usr/local/lib/python3.7/dist-packages/starlette/responses.py", line 282, in __call__
    stat_result = await anyio.to_thread.run_sync(os.stat, self.path)
  File "/usr/local/lib/python3.7/dist-packages/anyio/to_thread.py", line 29, in run_sync
    limiter=limiter)
  File "/usr/local/lib/python3.7/dist-packages/anyio/_backends/_asyncio.py", line 818, in run_sync_in_worker_thread
    return await future
  File "/usr/local/lib/python3.7/dist-packages/anyio/_backends/_asyncio.py", line 754, in run
    result = context.run(func, *args)
FileNotFoundError: [Errno 2] No such file or directory: './images/11/26/23/9/55.jpg'

During handling of the above exception, another exception occurred:

Traceback (most recent call last):
  File "/usr/local/lib/python3.7/dist-packages/uvicorn/protocols/http/httptools_impl.py", line 375, in run_asgi
    result = await app(self.scope, self.receive, self.send)
  File "/usr/local/lib/python3.7/dist-packages/uvicorn/middleware/proxy_headers.py", line 75, in __call__
    return await self.app(scope, receive, send)
  File "/usr/local/lib/python3.7/dist-packages/fastapi/applications.py", line 208, in __call__
    await super().__call__(scope, receive, send)
  File "/usr/local/lib/python3.7/dist-packages/starlette/applications.py", line 112, in __call__
    await self.middleware_stack(scope, receive, send)
  File "/usr/local/lib/python3.7/dist-packages/starlette/middleware/errors.py", line 181, in __call__
    raise exc
  File "/usr/local/lib/python3.7/dist-packages/starlette/middleware/errors.py", line 159, in __call__
    await self.app(scope, receive, _send)
  File "/usr/local/lib/python3.7/dist-packages/starlette/exceptions.py", line 82, in __call__
    raise exc
  File "/usr/local/lib/python3.7/dist-packages/starlette/exceptions.py", line 71, in __call__
    await self.app(scope, receive, sender)
  File "/usr/local/lib/python3.7/dist-packages/starlette/routing.py", line 656, in __call__
    await route.handle(scope, receive, send)
  File "/usr/local/lib/python3.7/dist-packages/starlette/routing.py", line 259, in handle
    await self.app(scope, receive, send)
  File "/usr/local/lib/python3.7/dist-packages/starlette/routing.py", line 64, in app
    await response(scope, receive, send)
  File "/usr/local/lib/python3.7/dist-packages/starlette/responses.py", line 285, in __call__
    raise RuntimeError(f"File at path {self.path} does not exist.")
RuntimeError: File at path ./images/11/26/23/9/55.jpg does not exist.
INFO:     10.20.41.203:0 - "GET /getImage?monthAndDayAndHourAndMinAndImageID=11/26/23/9/56.jpg HTTP/1.1" 200 OK
INFO:     10.20.41.203:0 - "GET /login HTTP/1.1" 200 OK
DEBUG:multipart.multipart:Calling on_field_start with no data
DEBUG:multipart.multipart:Calling on_field_name with data[0:3]
DEBUG:multipart.multipart:Calling on_field_data with data[4:22]
DEBUG:multipart.multipart:Calling on_field_end with no data
DEBUG:multipart.multipart:Calling on_end with no data
INFO:     10.20.41.203:0 - "POST /getToken HTTP/1.1" 200 OK
INFO:     10.20.41.203:0 - "GET / HTTP/1.1" 500 Internal Server Error
ERROR:    Exception in ASGI application
Traceback (most recent call last):
  File "/usr/local/lib/python3.7/dist-packages/uvicorn/protocols/http/httptools_impl.py", line 375, in run_asgi
    result = await app(self.scope, self.receive, self.send)
  File "/usr/local/lib/python3.7/dist-packages/uvicorn/middleware/proxy_headers.py", line 75, in __call__
    return await self.app(scope, receive, send)
  File "/usr/local/lib/python3.7/dist-packages/fastapi/applications.py", line 208, in __call__
    await super().__call__(scope, receive, send)
  File "/usr/local/lib/python3.7/dist-packages/starlette/applications.py", line 112, in __call__
    await self.middleware_stack(scope, receive, send)
  File "/usr/local/lib/python3.7/dist-packages/starlette/middleware/errors.py", line 181, in __call__
    raise exc
  File "/usr/local/lib/python3.7/dist-packages/starlette/middleware/errors.py", line 159, in __call__
    await self.app(scope, receive, _send)
  File "/usr/local/lib/python3.7/dist-packages/starlette/exceptions.py", line 82, in __call__
    raise exc
  File "/usr/local/lib/python3.7/dist-packages/starlette/exceptions.py", line 71, in __call__
    await self.app(scope, receive, sender)
  File "/usr/local/lib/python3.7/dist-packages/starlette/routing.py", line 656, in __call__
    await route.handle(scope, receive, send)
  File "/usr/local/lib/python3.7/dist-packages/starlette/routing.py", line 259, in handle
    await self.app(scope, receive, send)
  File "/usr/local/lib/python3.7/dist-packages/starlette/routing.py", line 61, in app
    response = await func(request)
  File "/usr/local/lib/python3.7/dist-packages/fastapi/routing.py", line 227, in app
    dependant=dependant, values=values, is_coroutine=is_coroutine
  File "/usr/local/lib/python3.7/dist-packages/fastapi/routing.py", line 161, in run_endpoint_function
    return await run_in_threadpool(dependant.call, **values)
  File "/usr/local/lib/python3.7/dist-packages/starlette/concurrency.py", line 39, in run_in_threadpool
    return await anyio.to_thread.run_sync(func, *args)
  File "/usr/local/lib/python3.7/dist-packages/anyio/to_thread.py", line 29, in run_sync
    limiter=limiter)
  File "/usr/local/lib/python3.7/dist-packages/anyio/_backends/_asyncio.py", line 818, in run_sync_in_worker_thread
    return await future
  File "/usr/local/lib/python3.7/dist-packages/anyio/_backends/_asyncio.py", line 754, in run
    result = context.run(func, *args)
  File "./main.py", line 43, in index
    f = open("./client/index.html","r")
FileNotFoundError: [Errno 2] No such file or directory: './client/index.html'
ERROR:uvicorn.error:Exception in ASGI application
Traceback (most recent call last):
  File "/usr/local/lib/python3.7/dist-packages/uvicorn/protocols/http/httptools_impl.py", line 375, in run_asgi
    result = await app(self.scope, self.receive, self.send)
  File "/usr/local/lib/python3.7/dist-packages/uvicorn/middleware/proxy_headers.py", line 75, in __call__
    return await self.app(scope, receive, send)
  File "/usr/local/lib/python3.7/dist-packages/fastapi/applications.py", line 208, in __call__
    await super().__call__(scope, receive, send)
  File "/usr/local/lib/python3.7/dist-packages/starlette/applications.py", line 112, in __call__
    await self.middleware_stack(scope, receive, send)
  File "/usr/local/lib/python3.7/dist-packages/starlette/middleware/errors.py", line 181, in __call__
    raise exc
  File "/usr/local/lib/python3.7/dist-packages/starlette/middleware/errors.py", line 159, in __call__
    await self.app(scope, receive, _send)
  File "/usr/local/lib/python3.7/dist-packages/starlette/exceptions.py", line 82, in __call__
    raise exc
  File "/usr/local/lib/python3.7/dist-packages/starlette/exceptions.py", line 71, in __call__
    await self.app(scope, receive, sender)
  File "/usr/local/lib/python3.7/dist-packages/starlette/routing.py", line 656, in __call__
    await route.handle(scope, receive, send)
  File "/usr/local/lib/python3.7/dist-packages/starlette/routing.py", line 259, in handle
    await self.app(scope, receive, send)
  File "/usr/local/lib/python3.7/dist-packages/starlette/routing.py", line 61, in app
    response = await func(request)
  File "/usr/local/lib/python3.7/dist-packages/fastapi/routing.py", line 227, in app
    dependant=dependant, values=values, is_coroutine=is_coroutine
  File "/usr/local/lib/python3.7/dist-packages/fastapi/routing.py", line 161, in run_endpoint_function
    return await run_in_threadpool(dependant.call, **values)
  File "/usr/local/lib/python3.7/dist-packages/starlette/concurrency.py", line 39, in run_in_threadpool
    return await anyio.to_thread.run_sync(func, *args)
  File "/usr/local/lib/python3.7/dist-packages/anyio/to_thread.py", line 29, in run_sync
    limiter=limiter)
  File "/usr/local/lib/python3.7/dist-packages/anyio/_backends/_asyncio.py", line 818, in run_sync_in_worker_thread
    return await future
  File "/usr/local/lib/python3.7/dist-packages/anyio/_backends/_asyncio.py", line 754, in run
    result = context.run(func, *args)
  File "./main.py", line 43, in index
    f = open("./client/index.html","r")
FileNotFoundError: [Errno 2] No such file or directory: './client/index.html'
INFO:     10.20.41.203:0 - "GET /getImage?monthAndDayAndHourAndMinAndImageID=11/26/23/9/56.jpg HTTP/1.1" 200 OK
INFO:     10.20.41.203:0 - "GET /getImage?monthAndDayAndHourAndMinAndImageID=11/26/23/9/57.jpg HTTP/1.1" 500 Internal Server Error
ERROR:    Exception in ASGI application
Traceback (most recent call last):
  File "/usr/local/lib/python3.7/dist-packages/starlette/responses.py", line 282, in __call__
    stat_result = await anyio.to_thread.run_sync(os.stat, self.path)
  File "/usr/local/lib/python3.7/dist-packages/anyio/to_thread.py", line 29, in run_sync
    limiter=limiter)
  File "/usr/local/lib/python3.7/dist-packages/anyio/_backends/_asyncio.py", line 818, in run_sync_in_worker_thread
    return await future
  File "/usr/local/lib/python3.7/dist-packages/anyio/_backends/_asyncio.py", line 754, in run
    result = context.run(func, *args)
FileNotFoundError: [Errno 2] No such file or directory: './images/11/26/23/9/57.jpg'

During handling of the above exception, another exception occurred:

Traceback (most recent call last):
  File "/usr/local/lib/python3.7/dist-packages/uvicorn/protocols/http/httptools_impl.py", line 375, in run_asgi
    result = await app(self.scope, self.receive, self.send)
  File "/usr/local/lib/python3.7/dist-packages/uvicorn/middleware/proxy_headers.py", line 75, in __call__
    return await self.app(scope, receive, send)
  File "/usr/local/lib/python3.7/dist-packages/fastapi/applications.py", line 208, in __call__
    await super().__call__(scope, receive, send)
  File "/usr/local/lib/python3.7/dist-packages/starlette/applications.py", line 112, in __call__
    await self.middleware_stack(scope, receive, send)
  File "/usr/local/lib/python3.7/dist-packages/starlette/middleware/errors.py", line 181, in __call__
    raise exc
  File "/usr/local/lib/python3.7/dist-packages/starlette/middleware/errors.py", line 159, in __call__
    await self.app(scope, receive, _send)
  File "/usr/local/lib/python3.7/dist-packages/starlette/exceptions.py", line 82, in __call__
    raise exc
  File "/usr/local/lib/python3.7/dist-packages/starlette/exceptions.py", line 71, in __call__
    await self.app(scope, receive, sender)
  File "/usr/local/lib/python3.7/dist-packages/starlette/routing.py", line 656, in __call__
    await route.handle(scope, receive, send)
  File "/usr/local/lib/python3.7/dist-packages/starlette/routing.py", line 259, in handle
    await self.app(scope, receive, send)
  File "/usr/local/lib/python3.7/dist-packages/starlette/routing.py", line 64, in app
    await response(scope, receive, send)
  File "/usr/local/lib/python3.7/dist-packages/starlette/responses.py", line 285, in __call__
    raise RuntimeError(f"File at path {self.path} does not exist.")
RuntimeError: File at path ./images/11/26/23/9/57.jpg does not exist.
ERROR:uvicorn.error:Exception in ASGI application
Traceback (most recent call last):
  File "/usr/local/lib/python3.7/dist-packages/starlette/responses.py", line 282, in __call__
    stat_result = await anyio.to_thread.run_sync(os.stat, self.path)
  File "/usr/local/lib/python3.7/dist-packages/anyio/to_thread.py", line 29, in run_sync
    limiter=limiter)
  File "/usr/local/lib/python3.7/dist-packages/anyio/_backends/_asyncio.py", line 818, in run_sync_in_worker_thread
    return await future
  File "/usr/local/lib/python3.7/dist-packages/anyio/_backends/_asyncio.py", line 754, in run
    result = context.run(func, *args)
FileNotFoundError: [Errno 2] No such file or directory: './images/11/26/23/9/57.jpg'

During handling of the above exception, another exception occurred:

Traceback (most recent call last):
  File "/usr/local/lib/python3.7/dist-packages/uvicorn/protocols/http/httptools_impl.py", line 375, in run_asgi
    result = await app(self.scope, self.receive, self.send)
  File "/usr/local/lib/python3.7/dist-packages/uvicorn/middleware/proxy_headers.py", line 75, in __call__
    return await self.app(scope, receive, send)
  File "/usr/local/lib/python3.7/dist-packages/fastapi/applications.py", line 208, in __call__
    await super().__call__(scope, receive, send)
  File "/usr/local/lib/python3.7/dist-packages/starlette/applications.py", line 112, in __call__
    await self.middleware_stack(scope, receive, send)
  File "/usr/local/lib/python3.7/dist-packages/starlette/middleware/errors.py", line 181, in __call__
    raise exc
  File "/usr/local/lib/python3.7/dist-packages/starlette/middleware/errors.py", line 159, in __call__
    await self.app(scope, receive, _send)
  File "/usr/local/lib/python3.7/dist-packages/starlette/exceptions.py", line 82, in __call__
    raise exc
  File "/usr/local/lib/python3.7/dist-packages/starlette/exceptions.py", line 71, in __call__
    await self.app(scope, receive, sender)
  File "/usr/local/lib/python3.7/dist-packages/starlette/routing.py", line 656, in __call__
    await route.handle(scope, receive, send)
  File "/usr/local/lib/python3.7/dist-packages/starlette/routing.py", line 259, in handle
    await self.app(scope, receive, send)
  File "/usr/local/lib/python3.7/dist-packages/starlette/routing.py", line 64, in app
    await response(scope, receive, send)
  File "/usr/local/lib/python3.7/dist-packages/starlette/responses.py", line 285, in __call__
    raise RuntimeError(f"File at path {self.path} does not exist.")
RuntimeError: File at path ./images/11/26/23/9/57.jpg does not exist.
INFO:     10.20.41.203:0 - "GET /getImage?monthAndDayAndHourAndMinAndImageID=11/26/23/9/59.jpg HTTP/1.1" 200 OK
INFO:     10.20.40.10:0 - "GET /getMonths_images HTTP/1.1" 200 OK
INFO:     10.20.40.10:0 - "GET /login HTTP/1.1" 200 OK
DEBUG:multipart.multipart:Calling on_field_start with no data
DEBUG:multipart.multipart:Calling on_field_name with data[0:3]
DEBUG:multipart.multipart:Calling on_field_data with data[4:22]
DEBUG:multipart.multipart:Calling on_field_end with no data
DEBUG:multipart.multipart:Calling on_end with no data
INFO:     10.20.40.10:0 - "POST /getToken HTTP/1.1" 200 OK
INFO:     10.20.40.10:0 - "GET / HTTP/1.1" 500 Internal Server Error
ERROR:    Exception in ASGI application
Traceback (most recent call last):
  File "/usr/local/lib/python3.7/dist-packages/uvicorn/protocols/http/httptools_impl.py", line 375, in run_asgi
    result = await app(self.scope, self.receive, self.send)
  File "/usr/local/lib/python3.7/dist-packages/uvicorn/middleware/proxy_headers.py", line 75, in __call__
    return await self.app(scope, receive, send)
  File "/usr/local/lib/python3.7/dist-packages/fastapi/applications.py", line 208, in __call__
    await super().__call__(scope, receive, send)
  File "/usr/local/lib/python3.7/dist-packages/starlette/applications.py", line 112, in __call__
    await self.middleware_stack(scope, receive, send)
  File "/usr/local/lib/python3.7/dist-packages/starlette/middleware/errors.py", line 181, in __call__
    raise exc
  File "/usr/local/lib/python3.7/dist-packages/starlette/middleware/errors.py", line 159, in __call__
    await self.app(scope, receive, _send)
  File "/usr/local/lib/python3.7/dist-packages/starlette/exceptions.py", line 82, in __call__
    raise exc
  File "/usr/local/lib/python3.7/dist-packages/starlette/exceptions.py", line 71, in __call__
    await self.app(scope, receive, sender)
  File "/usr/local/lib/python3.7/dist-packages/starlette/routing.py", line 656, in __call__
    await route.handle(scope, receive, send)
  File "/usr/local/lib/python3.7/dist-packages/starlette/routing.py", line 259, in handle
    await self.app(scope, receive, send)
  File "/usr/local/lib/python3.7/dist-packages/starlette/routing.py", line 61, in app
    response = await func(request)
  File "/usr/local/lib/python3.7/dist-packages/fastapi/routing.py", line 227, in app
    dependant=dependant, values=values, is_coroutine=is_coroutine
  File "/usr/local/lib/python3.7/dist-packages/fastapi/routing.py", line 161, in run_endpoint_function
    return await run_in_threadpool(dependant.call, **values)
  File "/usr/local/lib/python3.7/dist-packages/starlette/concurrency.py", line 39, in run_in_threadpool
    return await anyio.to_thread.run_sync(func, *args)
  File "/usr/local/lib/python3.7/dist-packages/anyio/to_thread.py", line 29, in run_sync
    limiter=limiter)
  File "/usr/local/lib/python3.7/dist-packages/anyio/_backends/_asyncio.py", line 818, in run_sync_in_worker_thread
    return await future
  File "/usr/local/lib/python3.7/dist-packages/anyio/_backends/_asyncio.py", line 754, in run
    result = context.run(func, *args)
  File "./main.py", line 43, in index
    f = open("./client/index.html","r")
FileNotFoundError: [Errno 2] No such file or directory: './client/index.html'
ERROR:uvicorn.error:Exception in ASGI application
Traceback (most recent call last):
  File "/usr/local/lib/python3.7/dist-packages/uvicorn/protocols/http/httptools_impl.py", line 375, in run_asgi
    result = await app(self.scope, self.receive, self.send)
  File "/usr/local/lib/python3.7/dist-packages/uvicorn/middleware/proxy_headers.py", line 75, in __call__
    return await self.app(scope, receive, send)
  File "/usr/local/lib/python3.7/dist-packages/fastapi/applications.py", line 208, in __call__
    await super().__call__(scope, receive, send)
  File "/usr/local/lib/python3.7/dist-packages/starlette/applications.py", line 112, in __call__
    await self.middleware_stack(scope, receive, send)
  File "/usr/local/lib/python3.7/dist-packages/starlette/middleware/errors.py", line 181, in __call__
    raise exc
  File "/usr/local/lib/python3.7/dist-packages/starlette/middleware/errors.py", line 159, in __call__
    await self.app(scope, receive, _send)
  File "/usr/local/lib/python3.7/dist-packages/starlette/exceptions.py", line 82, in __call__
    raise exc
  File "/usr/local/lib/python3.7/dist-packages/starlette/exceptions.py", line 71, in __call__
    await self.app(scope, receive, sender)
  File "/usr/local/lib/python3.7/dist-packages/starlette/routing.py", line 656, in __call__
    await route.handle(scope, receive, send)
  File "/usr/local/lib/python3.7/dist-packages/starlette/routing.py", line 259, in handle
    await self.app(scope, receive, send)
  File "/usr/local/lib/python3.7/dist-packages/starlette/routing.py", line 61, in app
    response = await func(request)
  File "/usr/local/lib/python3.7/dist-packages/fastapi/routing.py", line 227, in app
    dependant=dependant, values=values, is_coroutine=is_coroutine
  File "/usr/local/lib/python3.7/dist-packages/fastapi/routing.py", line 161, in run_endpoint_function
    return await run_in_threadpool(dependant.call, **values)
  File "/usr/local/lib/python3.7/dist-packages/starlette/concurrency.py", line 39, in run_in_threadpool
    return await anyio.to_thread.run_sync(func, *args)
  File "/usr/local/lib/python3.7/dist-packages/anyio/to_thread.py", line 29, in run_sync
    limiter=limiter)
  File "/usr/local/lib/python3.7/dist-packages/anyio/_backends/_asyncio.py", line 818, in run_sync_in_worker_thread
    return await future
  File "/usr/local/lib/python3.7/dist-packages/anyio/_backends/_asyncio.py", line 754, in run
    result = context.run(func, *args)
  File "./main.py", line 43, in index
    f = open("./client/index.html","r")
FileNotFoundError: [Errno 2] No such file or directory: './client/index.html'
INFO:     10.20.40.10:0 - "GET /getMonths_images HTTP/1.1" 200 OK
WARNING:  WatchGodReload detected file change in '['/root/IT3530-Project/server/main.py']'. Reloading...
INFO:     Shutting down
INFO:uvicorn.error:Shutting down
INFO:     Waiting for application shutdown.
INFO:uvicorn.error:Waiting for application shutdown.
INFO:     Application shutdown complete.
INFO:uvicorn.error:Application shutdown complete.
INFO:     Finished server process [839]
INFO:uvicorn.error:Finished server process [839]
ERROR:    Error loading ASGI app. Could not import module "main".
WARNING:  WatchGodReload detected file change in '['/root/IT3530-Project/server/main.py']'. Reloading...
./main.py:9: RuntimeWarning: This channel is already in use, continuing anyway.  Use GPIO.setwarnings(False) to disable warnings.
  GPIO.setup(20, GPIO.OUT)
INFO:     Started server process [2810]
INFO:uvicorn.error:Started server process [2810]
INFO:     Waiting for application startup.
INFO:uvicorn.error:Waiting for application startup.
INFO:     Application startup complete.
INFO:uvicorn.error:Application startup complete.
INFO:     10.20.40.10:0 - "GET /docs HTTP/1.1" 200 OK
INFO:     10.20.40.10:0 - "GET /openapi.json HTTP/1.1" 200 OK
INFO:     10.20.41.203:0 - "GET / HTTP/1.1" 500 Internal Server Error
ERROR:    Exception in ASGI application
Traceback (most recent call last):
  File "/usr/local/lib/python3.7/dist-packages/uvicorn/protocols/http/httptools_impl.py", line 375, in run_asgi
    result = await app(self.scope, self.receive, self.send)
  File "/usr/local/lib/python3.7/dist-packages/uvicorn/middleware/proxy_headers.py", line 75, in __call__
    return await self.app(scope, receive, send)
  File "/usr/local/lib/python3.7/dist-packages/fastapi/applications.py", line 208, in __call__
    await super().__call__(scope, receive, send)
  File "/usr/local/lib/python3.7/dist-packages/starlette/applications.py", line 112, in __call__
    await self.middleware_stack(scope, receive, send)
  File "/usr/local/lib/python3.7/dist-packages/starlette/middleware/errors.py", line 181, in __call__
    raise exc
  File "/usr/local/lib/python3.7/dist-packages/starlette/middleware/errors.py", line 159, in __call__
    await self.app(scope, receive, _send)
  File "/usr/local/lib/python3.7/dist-packages/starlette/exceptions.py", line 82, in __call__
    raise exc
  File "/usr/local/lib/python3.7/dist-packages/starlette/exceptions.py", line 71, in __call__
    await self.app(scope, receive, sender)
  File "/usr/local/lib/python3.7/dist-packages/starlette/routing.py", line 656, in __call__
    await route.handle(scope, receive, send)
  File "/usr/local/lib/python3.7/dist-packages/starlette/routing.py", line 259, in handle
    await self.app(scope, receive, send)
  File "/usr/local/lib/python3.7/dist-packages/starlette/routing.py", line 61, in app
    response = await func(request)
  File "/usr/local/lib/python3.7/dist-packages/fastapi/routing.py", line 227, in app
    dependant=dependant, values=values, is_coroutine=is_coroutine
  File "/usr/local/lib/python3.7/dist-packages/fastapi/routing.py", line 161, in run_endpoint_function
    return await run_in_threadpool(dependant.call, **values)
  File "/usr/local/lib/python3.7/dist-packages/starlette/concurrency.py", line 39, in run_in_threadpool
    return await anyio.to_thread.run_sync(func, *args)
  File "/usr/local/lib/python3.7/dist-packages/anyio/to_thread.py", line 29, in run_sync
    limiter=limiter)
  File "/usr/local/lib/python3.7/dist-packages/anyio/_backends/_asyncio.py", line 818, in run_sync_in_worker_thread
    return await future
  File "/usr/local/lib/python3.7/dist-packages/anyio/_backends/_asyncio.py", line 754, in run
    result = context.run(func, *args)
  File "./main.py", line 43, in index
    f = open("./client/index.html","r")
FileNotFoundError: [Errno 2] No such file or directory: './client/index.html'
ERROR:uvicorn.error:Exception in ASGI application
Traceback (most recent call last):
  File "/usr/local/lib/python3.7/dist-packages/uvicorn/protocols/http/httptools_impl.py", line 375, in run_asgi
    result = await app(self.scope, self.receive, self.send)
  File "/usr/local/lib/python3.7/dist-packages/uvicorn/middleware/proxy_headers.py", line 75, in __call__
    return await self.app(scope, receive, send)
  File "/usr/local/lib/python3.7/dist-packages/fastapi/applications.py", line 208, in __call__
    await super().__call__(scope, receive, send)
  File "/usr/local/lib/python3.7/dist-packages/starlette/applications.py", line 112, in __call__
    await self.middleware_stack(scope, receive, send)
  File "/usr/local/lib/python3.7/dist-packages/starlette/middleware/errors.py", line 181, in __call__
    raise exc
  File "/usr/local/lib/python3.7/dist-packages/starlette/middleware/errors.py", line 159, in __call__
    await self.app(scope, receive, _send)
  File "/usr/local/lib/python3.7/dist-packages/starlette/exceptions.py", line 82, in __call__
    raise exc
  File "/usr/local/lib/python3.7/dist-packages/starlette/exceptions.py", line 71, in __call__
    await self.app(scope, receive, sender)
  File "/usr/local/lib/python3.7/dist-packages/starlette/routing.py", line 656, in __call__
    await route.handle(scope, receive, send)
  File "/usr/local/lib/python3.7/dist-packages/starlette/routing.py", line 259, in handle
    await self.app(scope, receive, send)
  File "/usr/local/lib/python3.7/dist-packages/starlette/routing.py", line 61, in app
    response = await func(request)
  File "/usr/local/lib/python3.7/dist-packages/fastapi/routing.py", line 227, in app
    dependant=dependant, values=values, is_coroutine=is_coroutine
  File "/usr/local/lib/python3.7/dist-packages/fastapi/routing.py", line 161, in run_endpoint_function
    return await run_in_threadpool(dependant.call, **values)
  File "/usr/local/lib/python3.7/dist-packages/starlette/concurrency.py", line 39, in run_in_threadpool
    return await anyio.to_thread.run_sync(func, *args)
  File "/usr/local/lib/python3.7/dist-packages/anyio/to_thread.py", line 29, in run_sync
    limiter=limiter)
  File "/usr/local/lib/python3.7/dist-packages/anyio/_backends/_asyncio.py", line 818, in run_sync_in_worker_thread
    return await future
  File "/usr/local/lib/python3.7/dist-packages/anyio/_backends/_asyncio.py", line 754, in run
    result = context.run(func, *args)
  File "./main.py", line 43, in index
    f = open("./client/index.html","r")
FileNotFoundError: [Errno 2] No such file or directory: './client/index.html'
INFO:     10.20.41.203:0 - "GET /getMonths HTTP/1.1" 404 Not Found
INFO:     10.20.41.203:0 - "GET /getMonths_images HTTP/1.1" 200 OK
INFO:     10.20.40.10:0 - "GET / HTTP/1.1" 200 OK
INFO:     10.20.40.10:0 - "GET /getMonths_images HTTP/1.1" 200 OK
INFO:     10.20.40.10:0 - "GET / HTTP/1.1" 200 OK
INFO:     10.20.40.10:0 - "GET /getMonths_images HTTP/1.1" 200 OK
INFO:     10.20.40.10:0 - "GET /login HTTP/1.1" 200 OK
DEBUG:multipart.multipart:Calling on_field_start with no data
DEBUG:multipart.multipart:Calling on_field_name with data[0:3]
DEBUG:multipart.multipart:Calling on_field_data with data[4:22]
DEBUG:multipart.multipart:Calling on_field_end with no data
DEBUG:multipart.multipart:Calling on_end with no data
INFO:     10.20.40.10:0 - "POST /getToken HTTP/1.1" 200 OK
INFO:     10.20.40.10:0 - "GET / HTTP/1.1" 200 OK
INFO:     10.20.40.10:0 - "GET /getMonths_images HTTP/1.1" 200 OK
INFO:     10.20.40.10:0 - "GET / HTTP/1.1" 200 OK
INFO:     10.20.40.10:0 - "GET /getMonths_images HTTP/1.1" 200 OK
INFO:     10.20.41.203:0 - "GET / HTTP/1.1" 200 OK
INFO:     10.20.41.203:0 - "GET /getMonths_images HTTP/1.1" 200 OK
INFO:     10.20.41.203:0 - "GET / HTTP/1.1" 200 OK
INFO:     10.20.41.203:0 - "GET /getMonths_images HTTP/1.1" 200 OK
INFO:     10.20.40.10:0 - "GET / HTTP/1.1" 200 OK
INFO:     10.20.40.10:0 - "GET /getMonths_images HTTP/1.1" 200 OK
INFO:     10.20.40.10:0 - "GET / HTTP/1.1" 200 OK
INFO:     10.20.40.10:0 - "GET /getMonths_images HTTP/1.1" 200 OK
INFO:     10.20.40.10:0 - "GET / HTTP/1.1" 200 OK
INFO:     10.20.40.10:0 - "GET /getMonths_images HTTP/1.1" 200 OK
INFO:     10.20.40.10:0 - "GET / HTTP/1.1" 200 OK
INFO:     10.20.40.10:0 - "GET /getMonths_images HTTP/1.1" 200 OK
INFO:     10.20.40.10:0 - "GET / HTTP/1.1" 200 OK
INFO:     10.20.40.10:0 - "GET /getMonths_images HTTP/1.1" 200 OK
INFO:     10.20.40.10:0 - "GET / HTTP/1.1" 200 OK
INFO:     10.20.40.10:0 - "GET /getMonths_images HTTP/1.1" 200 OK
INFO:     10.20.40.10:0 - "GET / HTTP/1.1" 200 OK
INFO:     10.20.40.10:0 - "GET /getMonths_audio HTTP/1.1" 200 OK
INFO:     10.20.40.10:0 - "GET /getMonths_images HTTP/1.1" 200 OK
INFO:     10.20.40.10:0 - "GET / HTTP/1.1" 200 OK
INFO:     10.20.40.10:0 - "GET /getMonths_images HTTP/1.1" 200 OK
INFO:     10.20.40.10:0 - "GET /getMonths_audio HTTP/1.1" 200 OK
INFO:     10.20.41.203:0 - "GET /docs HTTP/1.1" 200 OK
INFO:     10.20.41.203:0 - "GET /openapi.json HTTP/1.1" 200 OK
INFO:     10.20.40.10:0 - "GET / HTTP/1.1" 200 OK
INFO:     10.20.40.10:0 - "GET /getMonths_images HTTP/1.1" 200 OK
INFO:     10.20.40.10:0 - "GET /getMonths_audio HTTP/1.1" 200 OK
INFO:     10.20.40.10:0 - "GET /beep HTTP/1.1" 200 OK
INFO:     10.20.40.10:0 - "POST /text HTTP/1.1" 422 Unprocessable Entity
INFO:     10.20.40.10:0 - "POST /text?Text=AA HTTP/1.1" 200 OK
INFO:     10.20.40.10:0 - "GET /login HTTP/1.1" 200 OK
DEBUG:multipart.multipart:Calling on_field_start with no data
DEBUG:multipart.multipart:Calling on_field_name with data[0:3]
DEBUG:multipart.multipart:Calling on_field_data with data[4:22]
DEBUG:multipart.multipart:Calling on_field_end with no data
DEBUG:multipart.multipart:Calling on_end with no data
INFO:     10.20.40.10:0 - "POST /getToken HTTP/1.1" 200 OK
INFO:     10.20.40.10:0 - "GET / HTTP/1.1" 200 OK
INFO:     10.20.40.10:0 - "GET /getMonths_images HTTP/1.1" 200 OK
INFO:     10.20.40.10:0 - "GET /getMonths_audio HTTP/1.1" 200 OK
INFO:     10.20.40.10:0 - "POST /text HTTP/1.1" 422 Unprocessable Entity
INFO:     10.20.40.10:0 - "GET /docs HTTP/1.1" 200 OK
INFO:     10.20.40.10:0 - "GET /openapi.json HTTP/1.1" 200 OK
INFO:root:epd4in2 Demo
INFO:root:init and Clear
INFO:root:1.Drawing on the Horizontal image...
DEBUG:waveshare_epd.epd4in2:Horizontal
INFO:root:Goto Sleep...
DEBUG:waveshare_epd.epdconfig:spi end
DEBUG:waveshare_epd.epdconfig:close 5V, Module enters 0 power consumption ...
400
INFO:     10.20.40.10:0 - "POST /text?Text=A HTTP/1.1" 200 OK
INFO:     10.20.41.203:0 - "POST /text HTTP/1.1" 422 Unprocessable Entity
INFO:     10.20.41.203:0 - "GET / HTTP/1.1" 200 OK
INFO:     10.20.41.203:0 - "GET /getMonths_audio HTTP/1.1" 200 OK
INFO:     10.20.41.203:0 - "GET /getMonths_images HTTP/1.1" 200 OK
INFO:root:epd4in2 Demo
INFO:root:init and Clear
INFO:root:1.Drawing on the Horizontal image...
DEBUG:waveshare_epd.epd4in2:Horizontal
400
INFO:     10.20.41.203:0 - "GET /login HTTP/1.1" 200 OK
DEBUG:multipart.multipart:Calling on_field_start with no data
DEBUG:multipart.multipart:Calling on_field_name with data[0:3]
DEBUG:multipart.multipart:Calling on_field_data with data[4:22]
DEBUG:multipart.multipart:Calling on_field_end with no data
DEBUG:multipart.multipart:Calling on_end with no data
INFO:root:Goto Sleep...
INFO:     10.20.40.10:0 - "POST /getToken HTTP/1.1" 200 OK
INFO:     10.20.40.10:0 - "GET / HTTP/1.1" 200 OK
INFO:     10.20.40.10:0 - "GET /getMonths_audio HTTP/1.1" 200 OK
INFO:     10.20.40.10:0 - "GET /getMonths_images HTTP/1.1" 200 OK
DEBUG:waveshare_epd.epdconfig:spi end
DEBUG:waveshare_epd.epdconfig:close 5V, Module enters 0 power consumption ...
WARNING:  WatchGodReload detected file change in '['/root/IT3530-Project/server/main.py']'. Reloading...
INFO:     Shutting down
INFO:uvicorn.error:Shutting down
INFO:     Waiting for application shutdown.
INFO:uvicorn.error:Waiting for application shutdown.
INFO:     Application shutdown complete.
INFO:uvicorn.error:Application shutdown complete.
INFO:     Finished server process [2810]
INFO:uvicorn.error:Finished server process [2810]
ERROR:    Error loading ASGI app. Could not import module "main".
WARNING:  WatchGodReload detected file change in '['/root/IT3530-Project/server/main.py']'. Reloading...
INFO:     Started server process [3011]
INFO:uvicorn.error:Started server process [3011]
INFO:     Waiting for application startup.
INFO:uvicorn.error:Waiting for application startup.
INFO:     Application startup complete.
INFO:uvicorn.error:Application startup complete.
INFO:     10.20.41.203:0 - "GET / HTTP/1.1" 200 OK
INFO:     10.20.41.203:0 - "GET /getMonths_images HTTP/1.1" 200 OK
INFO:     10.20.41.203:0 - "GET /getMonths_audio HTTP/1.1" 200 OK
INFO:     10.20.41.203:0 - "GET / HTTP/1.1" 200 OK
INFO:     10.20.41.203:0 - "GET /getMonths_images HTTP/1.1" 200 OK
INFO:     10.20.41.203:0 - "GET /getMonths_audio HTTP/1.1" 200 OK
DEBUG:multipart.multipart:Calling on_field_start with no data
DEBUG:multipart.multipart:Calling on_field_name with data[0:4]
DEBUG:multipart.multipart:Calling on_field_data with data[5:12]
DEBUG:multipart.multipart:Calling on_field_end with no data
DEBUG:multipart.multipart:Calling on_end with no data
INFO:root:epd4in2 Demo
INFO:root:init and Clear
INFO:root:1.Drawing on the Horizontal image...
DEBUG:waveshare_epd.epd4in2:Horizontal
INFO:root:Goto Sleep...
DEBUG:waveshare_epd.epdconfig:spi end
DEBUG:waveshare_epd.epdconfig:close 5V, Module enters 0 power consumption ...
400
INFO:     10.20.41.203:0 - "POST /text HTTP/1.1" 200 OK
INFO:     10.20.40.10:0 - "GET /beep HTTP/1.1" 200 OK
INFO:     192.168.0.47:43008 - "GET / HTTP/1.1" 200 OK
INFO:     192.168.0.47:43008 - "GET /getMonths_images HTTP/1.1" 200 OK
INFO:     192.168.0.47:43010 - "GET /getMonths_audio HTTP/1.1" 200 OK
INFO:     192.168.0.47:43010 - "GET /favicon.ico HTTP/1.1" 404 Not Found
INFO:     192.168.0.47:43018 - "GET /login HTTP/1.1" 200 OK
DEBUG:multipart.multipart:Calling on_field_start with no data
DEBUG:multipart.multipart:Calling on_field_name with data[0:3]
DEBUG:multipart.multipart:Calling on_field_data with data[4:22]
DEBUG:multipart.multipart:Calling on_field_end with no data
DEBUG:multipart.multipart:Calling on_end with no data
INFO:     192.168.0.47:43020 - "POST /getToken HTTP/1.1" 200 OK
INFO:     192.168.0.47:43020 - "GET / HTTP/1.1" 200 OK
INFO:     192.168.0.47:43020 - "GET /getMonths_images HTTP/1.1" 200 OK
INFO:     192.168.0.47:43028 - "GET /getMonths_audio HTTP/1.1" 200 OK
INFO:     192.168.0.47:43030 - "GET /beep HTTP/1.1" 200 OK
WARNING:  WatchGodReload detected file change in '['/root/IT3530-Project/server/main.py']'. Reloading...
INFO:     Shutting down
INFO:uvicorn.error:Shutting down
INFO:     Waiting for application shutdown.
INFO:uvicorn.error:Waiting for application shutdown.
INFO:     Application shutdown complete.
INFO:uvicorn.error:Application shutdown complete.
INFO:     Finished server process [3011]
INFO:uvicorn.error:Finished server process [3011]
./main.py:9: RuntimeWarning: This channel is already in use, continuing anyway.  Use GPIO.setwarnings(False) to disable warnings.
  GPIO.setup(20, GPIO.OUT)
INFO:     Started server process [3068]
INFO:uvicorn.error:Started server process [3068]
INFO:     Waiting for application startup.
INFO:uvicorn.error:Waiting for application startup.
INFO:     Application startup complete.
INFO:uvicorn.error:Application startup complete.
WARNING:  WatchGodReload detected file change in '['/root/IT3530-Project/server/main.py']'. Reloading...
INFO:     Shutting down
INFO:uvicorn.error:Shutting down
INFO:     Waiting for application shutdown.
INFO:uvicorn.error:Waiting for application shutdown.
INFO:     Application shutdown complete.
INFO:uvicorn.error:Application shutdown complete.
INFO:     Finished server process [3068]
INFO:uvicorn.error:Finished server process [3068]
WARNING:  WatchGodReload detected file change in '['/root/IT3530-Project/server/main.py']'. Reloading...
./main.py:9: RuntimeWarning: This channel is already in use, continuing anyway.  Use GPIO.setwarnings(False) to disable warnings.
  GPIO.setup(20, GPIO.OUT)
INFO:     Started server process [3092]
INFO:uvicorn.error:Started server process [3092]
INFO:     Waiting for application startup.
INFO:uvicorn.error:Waiting for application startup.
INFO:     Application startup complete.
INFO:uvicorn.error:Application startup complete.
DEBUG:multipart.multipart:Calling on_field_start with no data
DEBUG:multipart.multipart:Calling on_field_name with data[0:4]
DEBUG:multipart.multipart:Calling on_field_data with data[5:9]
DEBUG:multipart.multipart:Calling on_field_end with no data
DEBUG:multipart.multipart:Calling on_end with no data
INFO:root:epd4in2 Demo
INFO:root:init and Clear
INFO:     192.168.0.47:43110 - "GET /beep HTTP/1.1" 200 OK
INFO:root:1.Drawing on the Horizontal image...
DEBUG:waveshare_epd.epd4in2:Horizontal
WARNING:  WatchGodReload detected file change in '['/root/IT3530-Project/server/main.py']'. Reloading...
INFO:     Shutting down
INFO:uvicorn.error:Shutting down
INFO:     Waiting for connections to close. (CTRL+C to force quit)
INFO:uvicorn.error:Waiting for connections to close. (CTRL+C to force quit)
INFO:root:Goto Sleep...
DEBUG:waveshare_epd.epdconfig:spi end
DEBUG:waveshare_epd.epdconfig:close 5V, Module enters 0 power consumption ...
400
INFO:     192.168.0.47:43108 - "POST /text HTTP/1.1" 200 OK
INFO:     Waiting for application shutdown.
INFO:uvicorn.error:Waiting for application shutdown.
INFO:     Application shutdown complete.
INFO:uvicorn.error:Application shutdown complete.
INFO:     Finished server process [3092]
INFO:uvicorn.error:Finished server process [3092]
WARNING:  WatchGodReload detected file change in '['/root/IT3530-Project/server/main.py']'. Reloading...
WARNING:  WatchGodReload detected file change in '['/root/IT3530-Project/server/beep.py']'. Reloading...
./main.py:9: RuntimeWarning: This channel is already in use, continuing anyway.  Use GPIO.setwarnings(False) to disable warnings.
  GPIO.setup(20, GPIO.OUT)
INFO:     Started server process [3115]
INFO:uvicorn.error:Started server process [3115]
INFO:     Waiting for application startup.
INFO:uvicorn.error:Waiting for application startup.
INFO:     Application startup complete.
INFO:uvicorn.error:Application startup complete.
INFO:     192.168.0.47:43144 - "GET /beep HTTP/1.1" 200 OK
INFO:     192.168.0.47:43134 - "GET /beep HTTP/1.1" 200 OK
INFO:     192.168.0.47:43146 - "GET /beep HTTP/1.1" 200 OK
INFO:     192.168.0.47:43148 - "GET /beep HTTP/1.1" 200 OK
INFO:     192.168.0.47:43150 - "GET /beep HTTP/1.1" 200 OK
INFO:     192.168.0.47:43152 - "GET /beep HTTP/1.1" 200 OK
INFO:     192.168.0.47:43160 - "GET /beep HTTP/1.1" 200 OK
INFO:     192.168.0.47:43160 - "GET /beep HTTP/1.1" 200 OK
INFO:     192.168.0.47:43162 - "GET /beep HTTP/1.1" 200 OK
WARNING:  WatchGodReload detected file change in '['/root/IT3530-Project/server/main.py']'. Reloading...
INFO:     Shutting down
INFO:uvicorn.error:Shutting down
INFO:     Waiting for application shutdown.
INFO:uvicorn.error:Waiting for application shutdown.
INFO:     Application shutdown complete.
INFO:uvicorn.error:Application shutdown complete.
INFO:     Finished server process [3115]
INFO:uvicorn.error:Finished server process [3115]
./main.py:9: RuntimeWarning: This channel is already in use, continuing anyway.  Use GPIO.setwarnings(False) to disable warnings.
  GPIO.setup(20, GPIO.OUT)
INFO:     Started server process [3197]
INFO:uvicorn.error:Started server process [3197]
INFO:     Waiting for application startup.
INFO:uvicorn.error:Waiting for application startup.
INFO:     Application startup complete.
INFO:uvicorn.error:Application startup complete.
INFO:     192.168.0.47:43178 - "GET /beep HTTP/1.1" 500 Internal Server Error
ERROR:    Exception in ASGI application
Traceback (most recent call last):
  File "/usr/local/lib/python3.7/dist-packages/uvicorn/protocols/http/httptools_impl.py", line 375, in run_asgi
    result = await app(self.scope, self.receive, self.send)
  File "/usr/local/lib/python3.7/dist-packages/uvicorn/middleware/proxy_headers.py", line 75, in __call__
    return await self.app(scope, receive, send)
  File "/usr/local/lib/python3.7/dist-packages/fastapi/applications.py", line 208, in __call__
    await super().__call__(scope, receive, send)
  File "/usr/local/lib/python3.7/dist-packages/starlette/applications.py", line 112, in __call__
    await self.middleware_stack(scope, receive, send)
  File "/usr/local/lib/python3.7/dist-packages/starlette/middleware/errors.py", line 181, in __call__
    raise exc
  File "/usr/local/lib/python3.7/dist-packages/starlette/middleware/errors.py", line 159, in __call__
    await self.app(scope, receive, _send)
  File "/usr/local/lib/python3.7/dist-packages/starlette/exceptions.py", line 82, in __call__
    raise exc
  File "/usr/local/lib/python3.7/dist-packages/starlette/exceptions.py", line 71, in __call__
    await self.app(scope, receive, sender)
  File "/usr/local/lib/python3.7/dist-packages/starlette/routing.py", line 656, in __call__
    await route.handle(scope, receive, send)
  File "/usr/local/lib/python3.7/dist-packages/starlette/routing.py", line 259, in handle
    await self.app(scope, receive, send)
  File "/usr/local/lib/python3.7/dist-packages/starlette/routing.py", line 61, in app
    response = await func(request)
  File "/usr/local/lib/python3.7/dist-packages/fastapi/routing.py", line 227, in app
    dependant=dependant, values=values, is_coroutine=is_coroutine
  File "/usr/local/lib/python3.7/dist-packages/fastapi/routing.py", line 161, in run_endpoint_function
    return await run_in_threadpool(dependant.call, **values)
  File "/usr/local/lib/python3.7/dist-packages/starlette/concurrency.py", line 39, in run_in_threadpool
    return await anyio.to_thread.run_sync(func, *args)
  File "/usr/local/lib/python3.7/dist-packages/anyio/to_thread.py", line 29, in run_sync
    limiter=limiter)
  File "/usr/local/lib/python3.7/dist-packages/anyio/_backends/_asyncio.py", line 818, in run_sync_in_worker_thread
    return await future
  File "/usr/local/lib/python3.7/dist-packages/anyio/_backends/_asyncio.py", line 754, in run
    result = context.run(func, *args)
  File "./main.py", line 148, in beep
    pin = GPIO.PWM(20, 600)
RuntimeError: A PWM object already exists for this GPIO channel
ERROR:uvicorn.error:Exception in ASGI application
Traceback (most recent call last):
  File "/usr/local/lib/python3.7/dist-packages/uvicorn/protocols/http/httptools_impl.py", line 375, in run_asgi
    result = await app(self.scope, self.receive, self.send)
  File "/usr/local/lib/python3.7/dist-packages/uvicorn/middleware/proxy_headers.py", line 75, in __call__
    return await self.app(scope, receive, send)
  File "/usr/local/lib/python3.7/dist-packages/fastapi/applications.py", line 208, in __call__
    await super().__call__(scope, receive, send)
  File "/usr/local/lib/python3.7/dist-packages/starlette/applications.py", line 112, in __call__
    await self.middleware_stack(scope, receive, send)
  File "/usr/local/lib/python3.7/dist-packages/starlette/middleware/errors.py", line 181, in __call__
    raise exc
  File "/usr/local/lib/python3.7/dist-packages/starlette/middleware/errors.py", line 159, in __call__
    await self.app(scope, receive, _send)
  File "/usr/local/lib/python3.7/dist-packages/starlette/exceptions.py", line 82, in __call__
    raise exc
  File "/usr/local/lib/python3.7/dist-packages/starlette/exceptions.py", line 71, in __call__
    await self.app(scope, receive, sender)
  File "/usr/local/lib/python3.7/dist-packages/starlette/routing.py", line 656, in __call__
    await route.handle(scope, receive, send)
  File "/usr/local/lib/python3.7/dist-packages/starlette/routing.py", line 259, in handle
    await self.app(scope, receive, send)
  File "/usr/local/lib/python3.7/dist-packages/starlette/routing.py", line 61, in app
    response = await func(request)
  File "/usr/local/lib/python3.7/dist-packages/fastapi/routing.py", line 227, in app
    dependant=dependant, values=values, is_coroutine=is_coroutine
  File "/usr/local/lib/python3.7/dist-packages/fastapi/routing.py", line 161, in run_endpoint_function
    return await run_in_threadpool(dependant.call, **values)
  File "/usr/local/lib/python3.7/dist-packages/starlette/concurrency.py", line 39, in run_in_threadpool
    return await anyio.to_thread.run_sync(func, *args)
  File "/usr/local/lib/python3.7/dist-packages/anyio/to_thread.py", line 29, in run_sync
    limiter=limiter)
  File "/usr/local/lib/python3.7/dist-packages/anyio/_backends/_asyncio.py", line 818, in run_sync_in_worker_thread
    return await future
  File "/usr/local/lib/python3.7/dist-packages/anyio/_backends/_asyncio.py", line 754, in run
    result = context.run(func, *args)
  File "./main.py", line 148, in beep
    pin = GPIO.PWM(20, 600)
RuntimeError: A PWM object already exists for this GPIO channel
INFO:     192.168.0.47:43180 - "GET /beep HTTP/1.1" 200 OK
INFO:     192.168.0.47:43180 - "GET /beep HTTP/1.1" 200 OK
INFO:     192.168.0.47:43182 - "GET /beep HTTP/1.1" 200 OK
WARNING:  WatchGodReload detected file change in '['/root/IT3530-Project/server/main.py']'. Reloading...
INFO:     Shutting down
INFO:uvicorn.error:Shutting down
INFO:     Waiting for application shutdown.
INFO:uvicorn.error:Waiting for application shutdown.
INFO:     Application shutdown complete.
INFO:uvicorn.error:Application shutdown complete.
INFO:     Finished server process [3197]
INFO:uvicorn.error:Finished server process [3197]
./main.py:9: RuntimeWarning: This channel is already in use, continuing anyway.  Use GPIO.setwarnings(False) to disable warnings.
  GPIO.setup(20, GPIO.OUT)
INFO:     Started server process [3237]
INFO:uvicorn.error:Started server process [3237]
INFO:     Waiting for application startup.
INFO:uvicorn.error:Waiting for application startup.
INFO:     Application startup complete.
INFO:uvicorn.error:Application startup complete.
INFO:     192.168.0.47:43208 - "GET /beep HTTP/1.1" 200 OK
INFO:     192.168.0.47:43210 - "GET / HTTP/1.1" 200 OK
INFO:     192.168.0.47:43210 - "GET /getMonths_images HTTP/1.1" 200 OK
INFO:     192.168.0.47:43212 - "GET /getMonths_audio HTTP/1.1" 200 OK
INFO:     192.168.0.47:43212 - "GET /beep HTTP/1.1" 200 OK
DEBUG:multipart.multipart:Calling on_field_start with no data
DEBUG:multipart.multipart:Calling on_field_name with data[0:4]
DEBUG:multipart.multipart:Calling on_field_data with data[5:16]
DEBUG:multipart.multipart:Calling on_field_end with no data
DEBUG:multipart.multipart:Calling on_end with no data
INFO:root:epd4in2 Demo
INFO:root:init and Clear
INFO:     192.168.0.47:43218 - "GET /getMonths_images HTTP/1.1" 200 OK
INFO:     192.168.0.47:43220 - "GET /getMonths_audio HTTP/1.1" 200 OK
INFO:root:1.Drawing on the Horizontal image...
DEBUG:waveshare_epd.epd4in2:Horizontal
INFO:root:Goto Sleep...
DEBUG:waveshare_epd.epdconfig:spi end
DEBUG:waveshare_epd.epdconfig:close 5V, Module enters 0 power consumption ...
WARNING:  WatchGodReload detected file change in '['/root/IT3530-Project/server/record.py']'. Reloading...
INFO:     Shutting down
INFO:uvicorn.error:Shutting down
INFO:     Waiting for application shutdown.
INFO:uvicorn.error:Waiting for application shutdown.
INFO:     Application shutdown complete.
INFO:uvicorn.error:Application shutdown complete.
INFO:     Finished server process [3237]
INFO:uvicorn.error:Finished server process [3237]
400
INFO:     Started server process [3302]
INFO:uvicorn.error:Started server process [3302]
INFO:     Waiting for application startup.
INFO:uvicorn.error:Waiting for application startup.
INFO:     Application startup complete.
INFO:uvicorn.error:Application startup complete.
WARNING:  WatchGodReload detected file change in '['/root/IT3530-Project/server/record.py']'. Reloading...
INFO:     Shutting down
INFO:uvicorn.error:Shutting down
INFO:     Waiting for application shutdown.
INFO:uvicorn.error:Waiting for application shutdown.
INFO:     Application shutdown complete.
INFO:uvicorn.error:Application shutdown complete.
INFO:     Finished server process [3302]
INFO:uvicorn.error:Finished server process [3302]
./main.py:9: RuntimeWarning: This channel is already in use, continuing anyway.  Use GPIO.setwarnings(False) to disable warnings.
  GPIO.setup(20, GPIO.OUT)
INFO:     Started server process [3325]
INFO:uvicorn.error:Started server process [3325]
INFO:     Waiting for application startup.
INFO:uvicorn.error:Waiting for application startup.
INFO:     Application startup complete.
INFO:uvicorn.error:Application startup complete.
WARNING:  WatchGodReload detected file change in '['/root/IT3530-Project/server/record.py']'. Reloading...
INFO:     Shutting down
INFO:uvicorn.error:Shutting down
INFO:     Waiting for application shutdown.
INFO:uvicorn.error:Waiting for application shutdown.
INFO:     Application shutdown complete.
INFO:uvicorn.error:Application shutdown complete.
INFO:     Finished server process [3325]
INFO:uvicorn.error:Finished server process [3325]
./main.py:9: RuntimeWarning: This channel is already in use, continuing anyway.  Use GPIO.setwarnings(False) to disable warnings.
  GPIO.setup(20, GPIO.OUT)
INFO:     Started server process [3355]
INFO:uvicorn.error:Started server process [3355]
INFO:     Waiting for application startup.
INFO:uvicorn.error:Waiting for application startup.
INFO:     Application startup complete.
INFO:uvicorn.error:Application startup complete.
WARNING:  WatchGodReload detected file change in '['/root/IT3530-Project/server/record.py']'. Reloading...
INFO:     Shutting down
INFO:uvicorn.error:Shutting down
INFO:     Waiting for application shutdown.
INFO:uvicorn.error:Waiting for application shutdown.
INFO:     Application shutdown complete.
INFO:uvicorn.error:Application shutdown complete.
INFO:     Finished server process [3355]
INFO:uvicorn.error:Finished server process [3355]
./main.py:9: RuntimeWarning: This channel is already in use, continuing anyway.  Use GPIO.setwarnings(False) to disable warnings.
  GPIO.setup(20, GPIO.OUT)
INFO:     Started server process [3373]
INFO:uvicorn.error:Started server process [3373]
INFO:     Waiting for application startup.
INFO:uvicorn.error:Waiting for application startup.
INFO:     Application startup complete.
INFO:uvicorn.error:Application startup complete.
WARNING:  WatchGodReload detected file change in '['/root/IT3530-Project/server/record.py']'. Reloading...
INFO:     Shutting down
INFO:uvicorn.error:Shutting down
INFO:     Waiting for application shutdown.
INFO:uvicorn.error:Waiting for application shutdown.
INFO:     Application shutdown complete.
INFO:uvicorn.error:Application shutdown complete.
INFO:     Finished server process [3373]
INFO:uvicorn.error:Finished server process [3373]
./main.py:9: RuntimeWarning: This channel is already in use, continuing anyway.  Use GPIO.setwarnings(False) to disable warnings.
  GPIO.setup(20, GPIO.OUT)
INFO:     Started server process [3837]
INFO:uvicorn.error:Started server process [3837]
INFO:     Waiting for application startup.
INFO:uvicorn.error:Waiting for application startup.
INFO:     Application startup complete.
INFO:uvicorn.error:Application startup complete.
WARNING:  WatchGodReload detected file change in '['/root/IT3530-Project/server/record.py']'. Reloading...
INFO:     Shutting down
INFO:uvicorn.error:Shutting down
INFO:     Waiting for application shutdown.
INFO:uvicorn.error:Waiting for application shutdown.
INFO:     Application shutdown complete.
INFO:uvicorn.error:Application shutdown complete.
INFO:     Finished server process [3837]
INFO:uvicorn.error:Finished server process [3837]
./main.py:9: RuntimeWarning: This channel is already in use, continuing anyway.  Use GPIO.setwarnings(False) to disable warnings.
  GPIO.setup(20, GPIO.OUT)
INFO:     Started server process [3841]
INFO:uvicorn.error:Started server process [3841]
INFO:     Waiting for application startup.
INFO:uvicorn.error:Waiting for application startup.
INFO:     Application startup complete.
INFO:uvicorn.error:Application startup complete.
INFO:     192.168.0.2:59146 - "GET /beep HTTP/1.1" 200 OK
INFO:     192.168.0.2:59194 - "GET /beep HTTP/1.1" 200 OK
INFO:     192.168.0.2:59213 - "GET /login HTTP/1.1" 200 OK
DEBUG:multipart.multipart:Calling on_field_start with no data
DEBUG:multipart.multipart:Calling on_field_name with data[0:3]
DEBUG:multipart.multipart:Calling on_field_data with data[4:22]
DEBUG:multipart.multipart:Calling on_field_end with no data
DEBUG:multipart.multipart:Calling on_end with no data
INFO:     192.168.0.2:59233 - "POST /getToken HTTP/1.1" 200 OK
INFO:     192.168.0.2:59233 - "GET / HTTP/1.1" 200 OK
INFO:     192.168.0.2:59233 - "GET /getMonths_images HTTP/1.1" 200 OK
INFO:     192.168.0.2:59234 - "GET /getMonths_audio HTTP/1.1" 200 OK
INFO:     192.168.0.2:59246 - "GET /beep HTTP/1.1" 200 OK
INFO:     192.168.0.2:59262 - "GET / HTTP/1.1" 200 OK
INFO:     192.168.0.2:59262 - "GET /getMonths_images HTTP/1.1" 200 OK
INFO:     192.168.0.2:59265 - "GET /getMonths_audio HTTP/1.1" 200 OK
INFO:     10.20.41.203:0 - "GET / HTTP/1.1" 200 OK
INFO:     10.20.41.203:0 - "GET /getMonths_images HTTP/1.1" 200 OK
INFO:     10.20.41.203:0 - "GET /getMonths_audio HTTP/1.1" 200 OK
INFO:     10.20.41.203:0 - "GET /login HTTP/1.1" 200 OK
DEBUG:multipart.multipart:Calling on_field_start with no data
DEBUG:multipart.multipart:Calling on_field_name with data[0:3]
DEBUG:multipart.multipart:Calling on_field_data with data[4:22]
DEBUG:multipart.multipart:Calling on_field_end with no data
DEBUG:multipart.multipart:Calling on_end with no data
INFO:     10.20.41.203:0 - "POST /getToken HTTP/1.1" 200 OK
INFO:     10.20.41.203:0 - "GET / HTTP/1.1" 200 OK
INFO:     10.20.41.203:0 - "GET /getMonths_images HTTP/1.1" 200 OK
INFO:     10.20.41.203:0 - "GET /getMonths_audio HTTP/1.1" 200 OK
